Workbook

Sheet ALL CONTENTS
T1: FRESH PRODUCTS FRESH PRODUCTS FRESH PRODUCTS FRESH PRODUCTS | AY1: FROZEN PRODUCTS | BN1: DRY PRODUCTS | CE1: Spices
A2: No. | B2: Code | C2: Origin | D2: Category | E2: Sub Category | F2: Out Sourced / Produced ? | G2: Regular /Occasional | H2: Recipe Name | I2: Recipe Reference | J2: Recipe No | K2: Code 1 | L2: Code 2 | M2: Ready Meal Code | N2: Alternative Code | O2: Description | P2: Unit Weight | Q2: Status | R2: One Mix Qty/ Qty Per Batch | S2: Number Of Units Per Pastry Sheet | T2: Onion Puree | U2: Cheddar Cheese | V2: 3Mm Sliced Onions | W2: 10Mm Diced Onions | X2: 10Mm Diced Potatoes | Y2: 3 X 3 X20Mm Shredded Carrots | Z2: 3Mm Shredded Cabbage | AA2: 10 X 10Mm Diced Carrots | AB2: Sliced Red Pepper | AC2: Diced Red Pepper 20Mm | AD2: Pepper Red - Cp Cut | AE2: Pepper Green - Cp Cut | AF2: Potato Diced 20Mm | AG2: Diced Onions 25Mm | AH2: Fresh Green Beans Baton (30-60Mm( | AI2: Baby Corn Diced | AJ2: Baton Carrot 2.5Mm | AK2: Savoy Cabbage Shredded Julian | AL2: Diced Green Pepper 25Mm | AM2: Chopped Onion 2-6 Mm | AN2: Fresh Coriander Chopped | AO2: Sliced Mushroom | AP2: Cp-Cut Onion | AQ2: Ginger Puree | AR2: Garlic Puree | AS2: Beansprouts Catering Pack | AT2: Julienne Chicken-Chicken Strips | AU2: Tims Natural Yoghurt | AV2: Single Cream | AW2: Dc4 Double Cream | AY2: Chicken | AZ2: Chicken Pakora | BA2: Chicken Fines | BB2: Lamb | BC2: Duck | BD2: Prawns | BE2: Potato Skins | BF2: Spring Onions | BG2: Diced Peppers Green | BH2: Diced Peppers Red | BI2: Mixed Vegetable | BJ2: Coriander | BK2: Spinach | BL2: Peas | BN2: Lemon Juice | BO2: Soya Mince | BP2: Bamboo Shoots | BQ2: Water Chestnuts | BR2: Wheat Flour (Victoria) | BS2: Gram Flour | BT2: Tomato Puree | BU2: Potato Starch | BV2: Potato Flakes | BW2: Kidney Beans | BX2: Sesame Seeds | BY2: Semolina | BZ2: Baking Powder | CA2: Breadcrumbs | CB2: Malt Vinegar | CC2: Rice Flour | CE2: Balti Curry Paste | CF2: Salt | CG2: Sugar | CH2: Cumin Seeds | CI2: Chilli Powder | CJ2: Tamarind Paste | CK2: Garam Masala
A3: 1 | B3: Chi|001 | C3: China | D3: Snacks | E3: Vegetable Samosa's | F3: Out Sourced | G3: Regular | H3: Vegetable Samosa | K3: VSB15G | L3: VS15G | N3: 1000 | O3: Vegetable Samosa Bite 15G | P3: 15 | Q3: Live | T3: =VLOOKUP(N3,('Master File'!$I$3:$I$220),1,FALSE) -> 1000
A4: =A3+1 -> 2 | B4: Chi|002 | C4: China | D4: Snacks | E4: Vegetable Spring roll's | F4: Out Sourced | G4: Regular | H4: Vegetable Spring roll | K4: VSR15G | L4: VSR15G | N4: 1001 | O4: Vegetable Spring Roll 15G | P4: 15 | Q4: Live | T4: =VLOOKUP(N4,('Master File'!$I$3:$I$220),1,FALSE) -> 1001
A5: =A4+1 -> 3 | B5: Chi|003 | C5: China | D5: Snacks | E5: Vegetable Spring roll's | F5: Out Sourced | G5: Regular | H5: Vegetable Spring roll | K5: VSR20G | L5: VSR20G | N5: 1002 | O5: Vegetable Spring Roll 20G | P5: 20 | Q5: Live | T5: =VLOOKUP(N5,('Master File'!$I$3:$I$220),1,FALSE) -> 1002
A6: =A5+1 -> 4 | B6: GAZ|001 | C6: GAZEBO | D6: Snacks | E6: Chicken Samosa's | F6: Produced | G6: Regular | H6: Chicken Tikka Samosa | I6: GFF106R | J6: 1 | K6: CTSXLJ120G | L6: CTS120G | N6: 1003 | O6: Chicken Tikka Samosa XL (Jumbo) 120G | P6: 120 | Q6: Live | R6: 320 | T6: =VLOOKUP(N6,('Master File'!$I$3:$I$220),1,FALSE) -> 1003
A7: =A6+1 -> 5 | B7: GAZ|002 | C7: GAZEBO | D7: Snacks | E7: Chicken Samosa's | F7: Produced | G7: Regular | H7: Chicken Tikka Samosa | I7: GFF004R | J7: 0 | K7: CTSL100G | L7: CTS100G | N7: 1004 | O7: Chicken Tikka Samosa Large 100G | P7: 100 | Q7: Live | R7: 600 | T7: =VLOOKUP(N7,('Master File'!$I$3:$I$220),1,FALSE) -> 1004
A8: =A7+1 -> 6 | B8: GAZ|003 | C8: GAZEBO | D8: Snacks | E8: Chicken Samosa's | F8: Produced | G8: Regular | H8: Chicken Tikka Samosa | I8: GFF004R | J8: 0 | K8: CTSL100GS | L8: CTS100GS | N8: 1005 | O8: Chicken Tikka Samosa Large 100G Seeded | P8: 100 | Q8: Live | R8: 600 | T8: =VLOOKUP(N8,('Master File'!$I$3:$I$220),1,FALSE) -> 1005
A9: =A8+1 -> 7 | B9: GAZ|004 | C9: GAZEBO | D9: Snacks | E9: Chicken Samosa's | F9: Produced | G9: Regular | H9: Chicken Tikka Samosa | I9: GFF004R | J9: 0 | K9: CTSM75G | L9: CTS75G | N9: 1006 | O9: Chicken Tikka Samosa Large 75G | P9: 75 | Q9: Live | R9: 920 | T9: =VLOOKUP(N9,('Master File'!$I$3:$I$220),1,FALSE) -> 1006
A10: =A9+1 -> 8 | B10: GAZ|005 | C10: GAZEBO | D10: Snacks | E10: Chicken Samosa's | F10: Produced | G10: Regular | H10: Chicken Tikka Samosa | I10: GFF004R | J10: 0 | K10: CTSC40G | L10: CTS40G | N10: 1007 | O10: Chicken Tikka Samosa Cocktail 40G | P10: 40 | Q10: Live | R10: 1800 | T10: =VLOOKUP(N10,('Master File'!$I$3:$I$220),1,FALSE) -> 1007
A11: =A10+1 -> 9 | B11: GAZ|006 | C11: GAZEBO | D11: Snacks | E11: Chicken Samosa's | F11: Produced | G11: Regular | H11: Chicken Tikka Samosa | I11: GFF004R | J11: 0 | K11: CTSC25G | L11: CTS25G | N11: 1008 | O11: Chicken Tikka Samosa Cocktail 25G | P11: 25 | Q11: Live | R11: 3200 | T11: =VLOOKUP(N11,('Master File'!$I$3:$I$220),1,FALSE) -> 1008
A12: =A11+1 -> 10 | B12: GAZ|007 | C12: GAZEBO | D12: Snacks | E12: Chicken Samosa's | F12: Produced | G12: Regular | H12: Jerk Chicken Samosa | I12: GFF106R | J12: 2 | K12: JCSL120G | L12: JCS120G | N12: 1009 | O12: Jerk Chicken Samosa Large 120G | P12: 120 | Q12: Live | R12: 225 | T12: =VLOOKUP(N12,('Master File'!$I$3:$I$220),1,FALSE) -> 1009
A13: =A12+1 -> 11 | B13: GAZ|008 | C13: GAZEBO | D13: Snacks | E13: Vegetable Samosa's | F13: Produced | G13: Regular | H13: Vegetable Samosa | I13: GFF003R | J13: 0 | K13: VSL100G | L13: VS100G | N13: 1010 | O13: Vegetable Samosa Large 100G | P13: 100 | Q13: Live | R13: 580 | S13: 4 | T13: =VLOOKUP(N13,('Master File'!$I$3:$I$220),1,FALSE) -> 1010 | W13: 1600 | X13: 24000 | AA13: 4000 | BJ13: 360 | BL13: 12000 | BN13: 800 | BT13: 960 | CE13: 1600 | CF13: 360 | CG13: 400 | CH13: 160 | CI13: 80 | CJ13: 80 | CK13: 80
A14: =A13+1 -> 12 | B14: GAZ|009 | C14: GAZEBO | D14: Snacks | E14: Vegetable Samosa's | F14: Produced | G14: Regular | H14: Vegetable Samosa | I14: GFF003R | J14: 0 | K14: VSL100GS | L14: VS100GS | N14: 1011 | O14: Vegetable Samosa Large 100G Seeded | P14: 100 | Q14: Live | R14: 580 | S14: 4 | T14: =VLOOKUP(N14,('Master File'!$I$3:$I$220),1,FALSE) -> 1011 | W14: 1600 | X14: 24000 | AA14: 4000 | BJ14: 360 | BL14: 12000 | BN14: 800 | BT14: 960 | CE14: 1600 | CF14: 360 | CG14: 400 | CH14: 160 | CI14: 80 | CJ14: 80 | CK14: 80
A15: =A14+1 -> 13 | B15: GAZ|010 | C15: GAZEBO | D15: Snacks | E15: Vegetable Samosa's | F15: Produced | G15: Regular | H15: Vegetable Samosa | I15: GFF003R | J15: 0 | K15: VSC25G | L15: VS25G | N15: 1012 | O15: Vegetable Samosa Cocktail 25G | P15: 25 | Q15: Live | R15: 3100 | S15: 8 | T15: =VLOOKUP(N15,('Master File'!$I$3:$I$220),1,FALSE) -> 1012 | W15: 1600 | X15: 24000 | AA15: 4000 | BJ15: 360 | BL15: 12000 | BN15: 800 | BT15: 960 | CE15: 1600 | CF15: 360 | CG15: 400 | CH15: 160 | CI15: 80 | CJ15: 80 | CK15: 80
A16: =A15+1 -> 14 | B16: GAZ|011 | C16: GAZEBO | D16: Snacks | E16: Vegetable Samosa's | F16: Produced | G16: Occasional | H16: Vegetable Samosa | I16: GFF003R | J16: 0 | K16: VSC25GS | L16: VS25GS | N16: 1013 | O16: Vegetable Samosa Cocktail 25G Seeded | P16: 25 | Q16: Live | R16: 3100 | S16: 8 | T16: =VLOOKUP(N16,('Master File'!$I$3:$I$220),1,FALSE) -> 1013 | W16: 1600 | X16: 24000 | AA16: 4000 | BJ16: 360 | BL16: 12000 | BN16: 800 | BT16: 960 | CE16: 1600 | CF16: 360 | CG16: 400 | CH16: 160 | CI16: 80 | CJ16: 80 | CK16: 80
A17: =A16+1 -> 15 | B17: GAZ|012 | C17: GAZEBO | D17: Snacks | E17: Vegetable Samosa's | F17: Produced | G17: Regular | H17: Vegetable Samosa | I17: GFF003R | J17: 0 | K17: VSC35G | L17: VS35G | N17: 1014 | O17: Vegetable Samosa Cocktail 35G | P17: 35 | Q17: Discontinued | R17: 0 | T17: =VLOOKUP(N17,('Master File'!$I$3:$I$220),1,FALSE) -> #N/A
A18: =A17+1 -> 16 | B18: GAZ|013 | C18: GAZEBO | D18: Snacks | E18: Vegetable Samosa's | F18: Produced | G18: Regular | H18: Vegetable Samosa | I18: GFF003R | J18: 0 | K18: VSC40G | L18: VS40G | N18: 1015 | O18: Vegetable Samosa Cocktail 40G | P18: 40 | Q18: Live | R18: 1650 | S18: 8 | T18: =VLOOKUP(N18,('Master File'!$I$3:$I$220),1,FALSE) -> 1015 | W18: 1600 | X18: 24000 | AA18: 4000 | BJ18: 360 | BL18: 12000 | BN18: 800 | BT18: 960 | CE18: 1600 | CF18: 360 | CG18: 400 | CH18: 160 | CI18: 80 | CJ18: 80 | CK18: 80
A19: =A18+1 -> 17 | B19: GAZ|014 | C19: GAZEBO | D19: Snacks | E19: Vegetable Samosa's | F19: Produced | G19: Regular | H19: Vegetable Samosa | I19: GFF039R | J19: 1 | K19: VSXLJ140G | L19: VS140G | N19: 1016 | O19: Vegetable Samosa XL (Jumbo) 140G | P19: 140 | Q19: Live | R19: 225 | S19: 3 | T19: =VLOOKUP(N19,('Master File'!$I$3:$I$220),1,FALSE) -> 1016
A20: =A19+1 -> 18 | B20: GAZ|015 | C20: GAZEBO | D20: Snacks | E20: Lamb Samosa's | F20: Produced | G20: Regular | H20: Lamb Samosa | I20: GFF005R | J20: 0 | K20: LSL100G | L20: LS100G | N20: 1017 | O20: Lamb Samosa Large 100G | P20: 100 | Q20: Live | R20: 700 | T20: =VLOOKUP(N20,('Master File'!$I$3:$I$220),1,FALSE) -> 1017
A21: =A20+1 -> 19 | B21: GAZ|016 | C21: GAZEBO | D21: Snacks | E21: Lamb Samosa's | F21: Produced | G21: Regular | H21: Lamb Samosa | I21: GFF005R | J21: 0 | K21: LSC25G | L21: LS25G | N21: 1018 | O21: Lamb Samosa Cocktail 25G | P21: 25 | Q21: Live | R21: 3000 | T21: =VLOOKUP(N21,('Master File'!$I$3:$I$220),1,FALSE) -> 1018
A22: =A21+1 -> 20 | B22: GAZ|017 | C22: GAZEBO | D22: Snacks | E22: Lamb Samosa's | F22: Produced | G22: Regular | H22: Lamb Samosa | I22: GFF005R | J22: 0 | K22: LSC40G | L22: LS40G | N22: 1019 | O22: Lamb Samosa Cocktail 40G | P22: 40 | Q22: Live | R22: 1600 | T22: =VLOOKUP(N22,('Master File'!$I$3:$I$220),1,FALSE) -> 1019
A23: =A22+1 -> 21 | B23: GAZ|018 | C23: GAZEBO | D23: Snacks | E23: Lamb Samosa's | F23: Produced | G23: Regular | H23: Lamb Samosa | I23: GFF040R | J23: 1 | K23: LSXLJ120G | L23: LS120G | N23: 1020 | O23: Lamb Samosa XL (Jumbo) 120G | P23: 120 | Q23: Live | R23: 250 | T23: =VLOOKUP(N23,('Master File'!$I$3:$I$220),1,FALSE) -> 1020
A24: =A23+1 -> 22 | B24: GAZ|019 | C24: GAZEBO | D24: Snacks | E24: Lamb Samosa's | F24: Produced | G24: Regular | H24: Lamb Samosa | I24: GFF005R | J24: 0 | K24: LSL75G | L24: LS75G | N24: 1021 | O24: Lamb Samosa Large 75G | P24: 75 | Q24: Live | R24: 1000 | T24: =VLOOKUP(N24,('Master File'!$I$3:$I$220),1,FALSE) -> 1021
A25: =A24+1 -> 23 | B25: GAZ|020 | C25: GAZEBO | D25: Snacks | E25: Lamb Samosa's | F25: Produced | G25: Regular | H25: Lamb Samosa | I25: GFF005R | J25: 0 | K25: LSL100GS | L25: LS100GS | N25: 1022 | O25: Lamb Samosa Large 100G Seeded | P25: 100 | Q25: Discontinued | R25: 700 | T25: =VLOOKUP(N25,('Master File'!$I$3:$I$220),1,FALSE) -> #N/A
A26: =A25+1 -> 24 | B26: GAZ|021 | C26: GAZEBO | D26: Snacks | E26: Chicken Spring roll's | F26: Produced | G26: Regular | H26: Chicken Spring roll | I26: GFF008R | J26: 0 | K26: CSRM50G | L26: CSR50G | N26: 1023 | O26: Chicken Spring Roll Medium 50G | P26: 50 | Q26: Live | R26: 600 | T26: =VLOOKUP(N26,('Master File'!$I$3:$I$220),1,FALSE) -> 1023
A27: =A26+1 -> 25 | B27: GAZ|022 | C27: GAZEBO | D27: Snacks | E27: Vegetable Spring roll's | F27: Produced | G27: Regular | H27: Vegetable Spring roll | J27: 0 | K27: VSR25G | L27: VSR25G | N27: 1024 | O27: Vegetable Spring Roll 25G | P27: 25 | Q27: Discontinued | T27: =VLOOKUP(N27,('Master File'!$I$3:$I$220),1,FALSE) -> #N/A
A28: =A27+1 -> 26 | B28: GAZ|023 | C28: GAZEBO | D28: Snacks | E28: Vegetable Spring roll's | F28: Produced | G28: Regular | H28: Vegetable Spring roll | I28: GFF006R | J28: 0 | K28: VSRL85G | L28: VSR85G | N28: 1025 | O28: Vegetable Spring Roll Large 85G | P28: 85 | Q28: Live | R28: 500 | T28: =VLOOKUP(N28,('Master File'!$I$3:$I$220),1,FALSE) -> 1025
A29: =A28+1 -> 27 | B29: GAZ|024 | C29: GAZEBO | D29: Snacks | E29: Vegetable Spring roll's | F29: Produced | G29: Regular | H29: Vegetable Spring roll | I29: GFF006R | J29: 0 | K29: VSRM50G | L29: VSR50G | N29: 1026 | O29: Vegetable Spring Roll Medium 50G | P29: 50 | Q29: Live | R29: 900 | T29: =VLOOKUP(N29,('Master File'!$I$3:$I$220),1,FALSE) -> 1026
A30: =A29+1 -> 28 | B30: GAZ|025 | C30: GAZEBO | D30: Snacks | E30: Duck Spring roll's | F30: Produced | G30: Regular | H30: Duck Spring roll | I30: GFF008R | K30: MDSRM50G | L30: DSR50G | N30: 1027 | O30: Duck Spring Roll Medium 50G | P30: 50 | Q30: Live | R30: 750 | T30: =VLOOKUP(N30,('Master File'!$I$3:$I$220),1,FALSE) -> 1027
A31: =A30+1 -> 29 | B31: GAZ|026 | C31: GAZEBO | D31: Snacks | E31: Onion Bhaji's | F31: Produced | G31: Regular | H31: Onion Bhaji | I31: GFF009-1R | K31: OBL100G | L31: OB100G | N31: 1028 | O31: Onion Bhaji Large 100G | P31: 100 | Q31: Live | R31: 450 | T31: =VLOOKUP(N31,('Master File'!$I$3:$I$220),1,FALSE) -> 1028
A32: =A31+1 -> 30 | B32: GAZ|027 | C32: GAZEBO | D32: Snacks | E32: Onion Bhaji's | F32: Produced | G32: Regular | H32: Onion Rings | K32: ORKG | L32: ORKG | N32: 1029 | O32: Onion Rings KG | P32: Var | Q32: Live | T32: =VLOOKUP(N32,('Master File'!$I$3:$I$220),1,FALSE) -> 1029
A33: =A32+1 -> 31 | B33: GAZ|028 | C33: GAZEBO | D33: Snacks | E33: Onion Bhaji's | F33: Produced | G33: Regular | H33: Shredded Onion Bhaji | I33: tbc | K33: SOBKG | L33: SOBKJ | N33: 1030 | O33: Shredded Onion Bhaji KG | P33: Var | Q33: Live | T33: =VLOOKUP(N33,('Master File'!$I$3:$I$220),1,FALSE) -> 1030
A34: =A33+1 -> 32 | B34: GAZ|029 | C34: GAZEBO | D34: Snacks | E34: Onion Bhaji's | F34: Produced | G34: Regular | H34: Spinach Bhaji | I34: GFF010-1R | K34: SBC30G | L34: SB30G | N34: 1031 | O34: Spinach Bhaji Cocktail 30G | P34: 30 | Q34: Live | R34: 550 | T34: =VLOOKUP(N34,('Master File'!$I$3:$I$220),1,FALSE) -> 1031
A35: =A34+1 -> 33 | B35: GAZ|030 | C35: GAZEBO | D35: Snacks | E35: Onion Bhaji's | F35: Produced | G35: Regular | H35: Spinach Bhaji | I35: GFF010-1R | K35: SBL100G | L35: SB100G | N35: 1032 | O35: Spinach Bhaji Large 100G | P35: 100 | Q35: Live | R35: 150 | T35: =VLOOKUP(N35,('Master File'!$I$3:$I$220),1,FALSE) -> 1032
A36: =A35+1 -> 34 | B36: GAZ|031 | C36: GAZEBO | D36: Snacks | E36: Onion Bhaji's | F36: Produced | G36: Regular | H36: Carrot Bhaji | I36: GFF032R | K36: C& OOnion BBhajis 20G | L36: COB20G | N36: 1033 | O36: Carrot & Onion Bhajis 20G | P36: 20 | Q36: Live | R36: 750 | T36: =VLOOKUP(N36,('Master File'!$I$3:$I$220),1,FALSE) -> 1033
A37: =A36+1 -> 35 | B37: GAZ|032 | C37: GAZEBO | D37: Snacks | E37: Onion Bhaji's | F37: Produced | G37: Regular | H37: Potato & Spinach Bhaji | I37: GFF037R | K37: P& SSpinach BBhaji 20G | L37: PSB20G | N37: 1034 | O37: Potato & Spinach Bhaji 20G | P37: 20 | Q37: Live | R37: 750 | T37: =VLOOKUP(N37,('Master File'!$I$3:$I$220),1,FALSE) -> 1034
A38: =A37+1 -> 36 | B38: GAZ|033 | C38: GAZEBO | D38: Snacks | E38: Onion Bhaji's | F38: Produced | G38: Regular | H38: Coconut & Coriander Bhaji | I38: tbc | K38: C& CCoriander BBhaji 20G | L38: CCB20G | N38: 1035 | O38: Coconut & Coriander Bhaji 20G | P38: 20 | Q38: Live | R38: TBC | T38: =VLOOKUP(N38,('Master File'!$I$3:$I$220),1,FALSE) -> 1035
A39: =A38+1 -> 37 | B39: GAZ|034 | C39: GAZEBO | D39: Snacks | E39: Pakora's | F39: Produced | G39: Regular | H39: Chicken Pakora | I39: GFF014R | K39: CPC | L39: CPCOCG | N39: 1036 | O39: Chicken Pakora Cocktail | P39: Var | Q39: Live | R39: 30 | T39: =VLOOKUP(N39,('Master File'!$I$3:$I$220),1,FALSE) -> 1036
A40: =A39+1 -> 38 | B40: GAZ|035 | C40: GAZEBO | D40: Snacks | E40: Pakora's | F40: Produced | G40: Regular | H40: Vegetable Pakora | I40: GFF013-3R | K40: VPB12G | L40: VP12G | N40: 1037 | O40: Vegetable Pakora Bite 12G | P40: 12 | Q40: Live | R40: 1600 | T40: =VLOOKUP(N40,('Master File'!$I$3:$I$220),1,FALSE) -> 1037
...

Sheet Sheet2
A1: Ingredients
A2: Steamed Potatoes | B2: Steamed Potatoes
A3: Steamed Peas | B3: Steamed Peas
A4: Steamed Diced Carrots | B4: Steamed Diced Carrots
A5: Diced Onions | B5: Diced Onions
A6: Tomato Puree | B6: Tomato Puree
A7: Lemon Juice | B7: Lemon Juice
A8: Green Coriander | B8: Green Coriander
A9: Curry Paste (Balti Sauce) | B9: Curry Paste (Balti Sauce)
A10: Salt | B10: Salt
A11: Sugar | B11: Sugar
A12: Cumin Seeds | B12: Cumin Seeds
A13: Chilli Powder | B13: Chilli Powder
... A35: Shredded Carrots | B35: Shredded Carrots
A36: Shredded Cabbage
A37: Sliced onions
A38: Diced peppers red
A39: Diced Green Peppers
A40: Soya sauce
A41: Hot pepper sauce
A42: Ginger puree
A43: Beans-sprouts
A44: Bamboo Shoots
A45: Water Chestnuts
A46: Spring Onions
A47: Green Diced Peppers
... A254: Kasuri Methi

Sheet Sheet3
A2: PRODUCT NAME
A3: ONION PUREE
A4: CHEDDAR CHEESE
A5: 3MM SLICED ONIONS
A6: 10MM DICED ONIONS
A7: 10MM DICED POTATOES
A8: 3 X 3 X20MM SHREDDED CARROTS
A9: 3MM SHREDDED CABBAGE
A10: 10 X 10MM DICED CARROTS
A11: SLICED RED PEPPER
A12: DICED RED PEPPER 20MM
A13: Pepper Red - CP cut
... A48: DRY GOODS
A49: LEMON JUICE | B49: Lemon Juice
A50: SOYA MINCE | B50: Soya Mince
A51: BAMBOO SHOOTS | B51: Bamboo Shoots
A52: WATER CHESTNUTS | B52: Water Chestnuts
A53: WHEAT FLOUR (Victoria) | B53: Wheat Flour (Victoria)
A54: GRAM FLOUR | B54: Gram Flour
A55: TOMATO PUREE | B55: Tomato Puree
A56: POTATO STARCH | B56: Potato Starch
A57: POTATO FLAKES | B57: Potato Flakes
A58: KIDNEY BEANS | B58: Kidney Beans
A59: SESAME SEEDS | B59: Sesame Seeds
A60: SEMOLINA | B60: Semolina
... A64: RICE FLOUR | B64: Rice Flour

Sheet Sheet1
A1: Supplier | B1: Description | C1: Status
A2: 3663 | B2: Peppered Chicken With Basil Pesto | 10G | C2: Live
A3: Dips | B3: Sweet Chilli Dip 40G | C3: Live
A4: Dips | B4: Spicy Tomato Dip 40G | C4: Live
A5: Fountain Frozen | B5: Garlic Breaded Mushrooms | C5: Live
A6: Fresh Olive | B6: Mozzarella Cheese & Sundried Tomato | 10G | C6: Live
A7: Funny Bones | B7: Mango Chilli Dip 40G | C7: Live
A8: Funny Bones | B8: Onion Rings | C8: Live
A9: Gazebo | B9: Onion Bhaji | 12G | C9: Live
A10: Gazebo | B10: Seeded Vegetable Samosas | 25G | C10: Live
A11: Gazebo | B11: Coconut & Coriander Bhaji | 20G | C11: Live
A12: Gazebo | B12: Spinach Pakora | 20G | C12: Live
A13: Gazebo | B13: Chicken Pakora | C13: Live
A14: Gazebo | B14: Red Onion Marmalade & Goat Cheese Tartlets | 18G | C14: Live
... A41: Trangs | B41: Square Prawn Toast | 15G | C41: Live

Sheet Master File
K1: Content Master 12/10/2015
A2: No. | B2: Origin | C2: Recipe Reference | D2: Recipe Name | E2: Category | F2: Sub Category | G2: Out Sourced / Produced ? | H2: Regular /Occasional | I2: Alternative Code | J2: Code | K2: Description | L2: Unit Weight | M2: Vegetarian (Y,N) | N2: Status | O2: One Mix Qty/ Qty Per Batch | P2: Description 2 | Q2: Number Of Person 5 | R2: Number Of Person 4 | S2: Number Of Person 3 | T2: Number Of Person 2 | U2: Number Of Person 1 | V2: No of Units Per Pastry Sheet | W2: Recipe Status On Master Ingredient File | X2: Allergen Name | Y2: Allergen Category | Z2: Date Created
A3: 4 | B3: GAZEBO | C3: GFF038R | D3: Chicken Tikka Samosa | E3: Snacks | F3: Chicken Samosa's | G3: Produced | H3: Regular | I3: 1003 | J3: CTS120G | K3: Chicken Tikka Samosa XL (Jumbo) 120G | L3: 120 | M3: N | N3: Live | O3: 320 | P3: =K3&" - "& C3 -> Chicken Tikka Samosa XL (Jumbo) 120G - GFF038R | Q3: 30 | R3: =($Q3/5)*4 -> 24 | S3: =($Q3/5)*3 -> 18 | T3: =($Q3/5)*2 -> 12 | U3: =($Q3/5)*1 -> 6 | V3: 3 | W3: Available | X3: Wheat, Soya | Y3: 3
A4: 5 | B4: GAZEBO | C4: GFF004R | D4: Chicken Tikka Samosa | E4: Snacks | F4: Chicken Samosa's | G4: Produced | H4: Regular | I4: 1004 | J4: CTS100G | K4: Chicken Tikka Samosa Large 100G | L4: 100 | M4: N | N4: Live | O4: 3100 | P4: =K4&" - "& C4 -> Chicken Tikka Samosa Large 100G - GFF004R | Q4: 25 | R4: =($Q4/5)*4 -> 20 | S4: =($Q4/5)*3 -> 15 | T4: =($Q4/5)*2 -> 10 | U4: =($Q4/5)*1 -> 5 | V4: 3 | W4: Available | X4: Wheat, Soya | Y4: 3
A5: 6 | B5: GAZEBO | C5: GFF004R | D5: Chicken Tikka Samosa | E5: Snacks | F5: Chicken Samosa's | G5: Produced | H5: Regular | I5: 1005 | J5: CTS100GS | K5: Chicken Tikka Samosa Large 100G Seeded | L5: 100 | M5: N | N5: Discontinued | O5: 600 | P5: =K5&" - "& C5 -> Chicken Tikka Samosa Large 100G Seeded - GFF004R | Q5: 15.5 | R5: =($Q5/5)*4 -> 12.4 | S5: =($Q5/5)*3 -> 9.3 | T5: =($Q5/5)*2 -> 6.2 | U5: =($Q5/5)*1 -> 3.1 | V5: 4 | W5: Available | X5: Wheat, Soya | Y5: 3
A6: 7 | B6: GAZEBO | C6: GFF004R | D6: Chicken Tikka Samosa | E6: Snacks | F6: Chicken Samosa's | G6: Produced | H6: Regular | I6: 1006 | J6: CTS75G | K6: Chicken Tikka Samosa Large 75G | L6: 75 | M6: N | N6: Live | O6: 4700 | P6: =K6&" - "& C6 -> Chicken Tikka Samosa Large 75G - GFF004R | Q6: 32 | R6: =($Q6/5)*4 -> 25.6 | S6: =($Q6/5)*3 -> 19.2 | T6: =($Q6/5)*2 -> 12.8 | U6: =($Q6/5)*1 -> 6.4 | V6: 4 | W6: Available | X6: Wheat, Soya | Y6: 3
A7: 8 | B7: GAZEBO | C7: GFF004R | D7: Chicken Tikka Samosa | E7: Snacks | F7: Chicken Samosa's | G7: Produced | H7: Regular | I7: 1007 | J7: CTS40G | K7: Chicken Tikka Samosa Cocktail 40G | L7: 40 | M7: N | N7: Live | O7: 9250 | P7: =K7&" - "& C7 -> Chicken Tikka Samosa Cocktail 40G - GFF004R | Q7: 40 | R7: =($Q7/5)*4 -> 32 | S7: =($Q7/5)*3 -> 24 | T7: =($Q7/5)*2 -> 16 | U7: =($Q7/5)*1 -> 8 | V7: 8 | W7: Available | X7: Wheat, Soya | Y7: 3
A8: 9 | B8: GAZEBO | C8: GFF004R | D8: Chicken Tikka Samosa | E8: Snacks | F8: Chicken Samosa's | G8: Produced | H8: Regular | I8: 1008 | J8: CTS25G | K8: Chicken Tikka Samosa Cocktail 25G | L8: 25 | M8: N | N8: Live | O8: 16500 | P8: =K8&" - "& C8 -> Chicken Tikka Samosa Cocktail 25G - GFF004R | Q8: 42.5 | R8: =($Q8/5)*4 -> 34 | S8: =($Q8/5)*3 -> 25.5 | T8: =($Q8/5)*2 -> 17 | U8: =($Q8/5)*1 -> 8.5 | V8: 8 | W8: Available | X8: Wheat, Soya | Y8: 3
A9: 10 | B9: GAZEBO | C9: GFF106R | D9: Jerk Chicken Samosa | E9: Snacks | F9: Chicken Samosa's | G9: Produced | H9: Regular | I9: 1009 | J9: JCS120G | K9: Jerk Chicken Samosa Large 120G | L9: 120 | M9: N | N9: Discontinued | O9: 225 | P9: =K9&" - "& C9 -> Jerk Chicken Samosa Large 120G - GFF106R | Q9: 10 | R9: =($Q9/5)*4 -> 8 | S9: =($Q9/5)*3 -> 6 | T9: =($Q9/5)*2 -> 4 | U9: =($Q9/5)*1 -> 2 | V9: 3 | W9: Available | X9: - | Y9: -
A10: 11 | B10: GAZEBO | C10: GFF003R | D10: Vegetable Samosa | E10: Snacks | F10: Vegetable Samosa's | G10: Produced | H10: Regular | I10: 1010 | J10: VS100G | K10: Vegetable Samosa Large 100G | L10: 100 | M10: Y | N10: Live | O10: 2320 | P10: =K10&" - "& C10 -> Vegetable Samosa Large 100G - GFF003R | Q10: 27 | R10: =($Q10/5)*4 -> 21.6 | S10: =($Q10/5)*3 -> 16.2 | T10: =($Q10/5)*2 -> 10.8 | U10: =($Q10/5)*1 -> 5.4 | V10: 4 | W10: Available | X10: Wheat | Y10: 3
A11: 12 | B11: GAZEBO | C11: GFF003R | D11: Vegetable Samosa | E11: Snacks | F11: Vegetable Samosa's | G11: Produced | H11: Regular | I11: 1011 | J11: VS100GS | K11: Vegetable Samosa Large 100G Seeded | L11: 100 | M11: Y | N11: Discontinued | O11: 580 | P11: =K11&" - "& C11 -> Vegetable Samosa Large 100G Seeded - GFF003R | Q11: 20 | R11: =($Q11/5)*4 -> 16 | S11: =($Q11/5)*3 -> 12 | T11: =($Q11/5)*2 -> 8 | U11: =($Q11/5)*1 -> 4 | V11: 4 | W11: Available | X11: Wheat | Y11: 3
A12: 13 | B12: GAZEBO | C12: GFF003R | D12: Vegetable Samosa | E12: Snacks | F12: Vegetable Samosa's | G12: Produced | H12: Regular | I12: 1012 | J12: VS25G | K12: Vegetable Samosa Cocktail 25G | L12: 25 | M12: Y | N12: Live | O12: 12400 | P12: =K12&" - "& C12 -> Vegetable Samosa Cocktail 25G - GFF003R | Q12: 35 | R12: =($Q12/5)*4 -> 28 | S12: =($Q12/5)*3 -> 21 | T12: =($Q12/5)*2 -> 14 | U12: =($Q12/5)*1 -> 7 | V12: 8 | W12: Available | X12: Wheat | Y12: 3
A13: 14 | B13: GAZEBO | C13: GFF003R | D13: Vegetable Samosa | E13: Snacks | F13: Vegetable Samosa's | G13: Produced | H13: Occasional | I13: 1013 | J13: VS25GS | K13: Vegetable Samosa Cocktail 25G Seeded | L13: 25 | M13: Y | N13: Live | O13: 12400 | P13: =K13&" - "& C13 -> Vegetable Samosa Cocktail 25G Seeded - GFF003R | Q13: 35 | R13: =($Q13/5)*4 -> 28 | S13: =($Q13/5)*3 -> 21 | T13: =($Q13/5)*2 -> 14 | U13: =($Q13/5)*1 -> 7 | V13: 8 | W13: Available | X13: Wheat | Y13: 3
A14: 16 | B14: GAZEBO | C14: GFF003R | D14: Vegetable Samosa | E14: Snacks | F14: Vegetable Samosa's | G14: Produced | H14: Regular | I14: 1015 | J14: VS40G | K14: Vegetable Samosa Cocktail 40G | L14: 40 | M14: Y | N14: Live | O14: 6600 | P14: =K14&" - "& C14 -> Vegetable Samosa Cocktail 40G - GFF003R | Q14: 35 | R14: =($Q14/5)*4 -> 28 | S14: =($Q14/5)*3 -> 21 | T14: =($Q14/5)*2 -> 14 | U14: =($Q14/5)*1 -> 7 | V14: 8 | W14: Available | X14: Wheat | Y14: 3
A15: 17 | B15: GAZEBO | C15: GFF039R | D15: Vegetable Samosa | E15: Snacks | F15: Vegetable Samosa's | G15: Produced | H15: Regular | I15: 1016 | J15: VS140G | K15: Vegetable Samosa XL (Jumbo) 140G | L15: 140 | M15: Y | N15: Live | O15: 225 | P15: =K15&" - "& C15 -> Vegetable Samosa XL (Jumbo) 140G - GFF039R | Q15: 27 | R15: =($Q15/5)*4 -> 21.6 | S15: =($Q15/5)*3 -> 16.2 | T15: =($Q15/5)*2 -> 10.8 | U15: =($Q15/5)*1 -> 5.4 | V15: 3 | W15: Available | X15: Wheat | Y15: 3
A16: 18 | B16: GAZEBO | C16: GFF005R | D16: Lamb Samosa | E16: Snacks | F16: Lamb Samosa's | G16: Produced | H16: Regular | I16: 1017 | J16: LS100G | K16: Lamb Samosa Large 100G | L16: 100 | M16: N | N16: Live | O16: 2600 | P16: =K16&" - "& C16 -> Lamb Samosa Large 100G - GFF005R | Q16: 27 | R16: =($Q16/5)*4 -> 21.6 | S16: =($Q16/5)*3 -> 16.2 | T16: =($Q16/5)*2 -> 10.8 | U16: =($Q16/5)*1 -> 5.4 | V16: 4 | W16: Available | X16: Soya, Wheat | Y16: 3
A17: 19 | B17: GAZEBO | C17: GFF005R | D17: Lamb Samosa | E17: Snacks | F17: Lamb Samosa's | G17: Produced | H17: Regular | I17: 1018 | J17: LS25G | K17: Lamb Samosa Cocktail 25G | L17: 25 | M17: N | N17: Live | O17: 13500 | P17: =K17&" - "& C17 -> Lamb Samosa Cocktail 25G - GFF005R | Q17: 37.5 | R17: =($Q17/5)*4 -> 30 | S17: =($Q17/5)*3 -> 22.5 | T17: =($Q17/5)*2 -> 15 | U17: =($Q17/5)*1 -> 7.5 | V17: 8 | W17: Available | X17: Soya, Wheat | Y17: 3
A18: 20 | B18: GAZEBO | C18: GFF005R | D18: Lamb Samosa | E18: Snacks | F18: Lamb Samosa's | G18: Produced | H18: Regular | I18: 1019 | J18: LS40G | K18: Lamb Samosa Cocktail 40G | L18: 40 | M18: N | N18: Live | O18: 6400 | P18: =K18&" - "& C18 -> Lamb Samosa Cocktail 40G - GFF005R | Q18: 35 | R18: =($Q18/5)*4 -> 28 | S18: =($Q18/5)*3 -> 21 | T18: =($Q18/5)*2 -> 14 | U18: =($Q18/5)*1 -> 7 | V18: 8 | W18: Available | X18: Soya, Wheat | Y18: 3
A19: 21 | B19: GAZEBO | C19: GFF005R | D19: Lamb Samosa | E19: Snacks | F19: Lamb Samosa's | G19: Produced | H19: Regular | I19: 1020 | J19: LS120G | K19: Lamb Samosa XL (Jumbo) 120G | L19: 120 | M19: N | N19: Live | O19: 2600 | P19: =K19&" - "& C19 -> Lamb Samosa XL (Jumbo) 120G - GFF005R | Q19: 27 | R19: =($Q19/5)*4 -> 21.6 | S19: =($Q19/5)*3 -> 16.2 | T19: =($Q19/5)*2 -> 10.8 | U19: =($Q19/5)*1 -> 5.4 | V19: 3 | W19: Available | X19: Soya, Wheat | Y19: 3
A20: 22 | B20: GAZEBO | C20: GFF005R | D20: Lamb Samosa | E20: Snacks | F20: Lamb Samosa's | G20: Produced | H20: Regular | I20: 1021 | J20: LS75G | K20: Lamb Samosa Large 75G | L20: 75 | M20: N | N20: Live | O20: 4000 | P20: =K20&" - "& C20 -> Lamb Samosa Large 75G - GFF005R | Q20: 27 | R20: =($Q20/5)*4 -> 21.6 | S20: =($Q20/5)*3 -> 16.2 | T20: =($Q20/5)*2 -> 10.8 | U20: =($Q20/5)*1 -> 5.4 | V20: 4 | W20: Available | X20: Soya, Wheat | Y20: 3
A21: 24 | B21: GAZEBO | C21: GFF007R | D21: Chicken Spring roll | E21: Snacks | F21: Chicken Spring roll's | G21: Produced | H21: Regular | I21: 1023 | J21: CSR50G | K21: Chicken Spring Roll Medium 50G | L21: 50 | M21: N | N21: Live | O21: 800 | P21: =K21&" - "& C21 -> Chicken Spring Roll Medium 50G - GFF007R | Q21: 30 | R21: =($Q21/5)*4 -> 24 | S21: =($Q21/5)*3 -> 18 | T21: =($Q21/5)*2 -> 12 | U21: =($Q21/5)*1 -> 6 | V21: 20 | W21: Available | X21: Wheat, Soya, Milk | Y21: 2
A22: 26 | B22: GAZEBO | C22: GFF006R | D22: Vegetable Spring roll | E22: Snacks | F22: Vegetable Spring roll's | G22: Produced | H22: Regular | I22: 1025 | J22: VSR85G | K22: Vegetable Spring Roll Large 85G | L22: 85 | M22: Y | N22: Discontinued | O22: 500 | P22: =K22&" - "& C22 -> Vegetable Spring Roll Large 85G - GFF006R | Q22: 24.2 | R22: =($Q22/5)*4 -> 19.36 | S22: =($Q22/5)*3 -> 14.52 | T22: =($Q22/5)*2 -> 9.68 | U22: =($Q22/5)*1 -> 4.84 | V22: 20 | W22: Available | X22: Wheat, Soya | Y22: 3 | Z22: D-17/08/2020
A23: 27 | B23: GAZEBO | C23: GFF006R | D23: Vegetable Spring roll | E23: Snacks | F23: Vegetable Spring roll's | G23: Produced | H23: Regular | I23: 1026 | J23: VSR50G | K23: Vegetable Spring Roll Medium 50G | L23: 50 | M23: Y | N23: Discontinued | O23: 900 | P23: =K23&" - "& C23 -> Vegetable Spring Roll Medium 50G - GFF006R | Q23: 35 | R23: =($Q23/5)*4 -> 28 | S23: =($Q23/5)*3 -> 21 | T23: =($Q23/5)*2 -> 14 | U23: =($Q23/5)*1 -> 7 | V23: 20 | W23: Available | X23: Wheat, Soya | Y23: 3 | Z23: D-17/08/2020
A24: 28 | B24: GAZEBO | C24: GFF008R | D24: Duck Spring roll | E24: Snacks | F24: Duck Spring roll's | G24: Produced | H24: Regular | I24: 1027 | J24: DSR50G | K24: Duck Spring Roll Medium 50G | L24: 50 | M24: N | N24: Discontinued | O24: 750 | P24: =K24&" - "& C24 -> Duck Spring Roll Medium 50G - GFF008R | Q24: 30 | R24: =($Q24/5)*4 -> 24 | S24: =($Q24/5)*3 -> 18 | T24: =($Q24/5)*2 -> 12 | U24: =($Q24/5)*1 -> 6 | V24: 20 | W24: Available | X24: Wheat, soya | Y24: 3 | Z24: D - 31/01/2024
A25: 29 | B25: GAZEBO | C25: GFF009-1R | D25: Onion Bhaji | E25: Snacks | F25: Onion Bhaji's | G25: Produced | H25: Regular | I25: 1028 | J25: OB100G | K25: Onion Bhaji Large 100G | L25: 100 | M25: Y | N25: Discontinued | O25: 525 | P25: =K25&" - "& C25 -> Onion Bhaji Large 100G - GFF009-1R | Q25: 21 | R25: =($Q25/5)*4 -> 16.8 | S25: =($Q25/5)*3 -> 12.6 | T25: =($Q25/5)*2 -> 8.4 | U25: =($Q25/5)*1 -> 4.2 | V25: 0 | W25: Available | X25: Wheat | Y25: 3
A26: 30 | B26: GAZEBO | C26: tbc | D26: Onion Rings | E26: Snacks | F26: Onion Bhaji's | G26: Produced | H26: Regular | I26: 1029 | J26: ORKG | K26: Onion Rings KG | L26: Var | M26: Y | N26: Discontinued | O26: tbc | P26: =K26&" - "& C26 -> Onion Rings KG - tbc | V26: 0 | W26: Not Available | X26: - | Y26: -
A27: 31 | B27: GAZEBO | C27: tbc | D27: Shredded Onion Bhaji | E27: Snacks | F27: Onion Bhaji's | G27: Produced | H27: Regular | I27: 1030 | J27: SOBKJ | K27: Shredded Onion Bhaji KG | L27: Var | M27: Y | N27: Discontinued | O27: tbc | P27: =K27&" - "& C27 -> Shredded Onion Bhaji KG - tbc | Q27: 60 | R27: 48 | S27: 36 | T27: 24 | U27: 12 | V27: 0 | W27: Not Available | X27: Wheat | Y27: 3
A28: 32 | B28: GAZEBO | C28: GFF010-1R | D28: Spinach Bhaji | E28: Snacks | F28: Onion Bhaji's | G28: Produced | H28: Regular | I28: 1031 | J28: SB30G | K28: Spinach Bhaji Cocktail 30G | L28: 30 | M28: Y | N28: Discontinued | O28: 520 | P28: =K28&" - "& C28 -> Spinach Bhaji Cocktail 30G - GFF010-1R | Q28: 64.63 | R28: 51.7 | S28: 38.5 | T28: 30.8 | U28: 15.4 | V28: 0 | W28: Available | X28: Wheat | Y28: 3 | Z28: D-09/09/2020
A29: 33 | B29: GAZEBO | C29: GFF010-1R | D29: Spinach Bhaji | E29: Snacks | F29: Onion Bhaji's | G29: Produced | H29: Regular | I29: 1032 | J29: SB100G | K29: Spinach Bhaji Large 100G | L29: 100 | M29: Y | N29: Discontinued | O29: 150 | P29: =K29&" - "& C29 -> Spinach Bhaji Large 100G - GFF010-1R | Q29: 38.5 | R29: 30.8 | S29: 23.1 | T29: 15.4 | U29: 7.7 | V29: 0 | W29: Available | X29: Wheat | Y29: 3 | Z29: D-09/09/2020
A30: 34 | B30: GAZEBO | C30: GFF032R | D30: Carrot & Coriander Bhaji | E30: Snacks | F30: Onion Bhaji's | G30: Produced | H30: Regular | I30: 1033 | J30: COB20G | K30: Carrot & Coriander Bhaji 20G | L30: 20 | M30: Y | N30: Discontinued | O30: 532 | P30: =K30&" - "& C30 -> Carrot & Coriander Bhaji 20G - GFF032R | Q30: 55 | R30: 44 | S30: 33 | T30: 22 | U30: 11 | V30: 0 | W30: Available | X30: Wheat | Y30: 3
A31: 35 | B31: GAZEBO | C31: GFF037R | D31: Potato & Spinach Bhaji | E31: Snacks | F31: Onion Bhaji's | G31: Produced | H31: Regular | I31: 1034 | J31: PSB20G | K31: Potato & Spinach Bhaji 20G | L31: 20 | M31: Y | N31: Discontinued | O31: 750 | P31: =K31&" - "& C31 -> Potato & Spinach Bhaji 20G - GFF037R | Q31: 55 | R31: =($Q31/5)*4 -> 44 | S31: =($Q31/5)*3 -> 33 | T31: =($Q31/5)*2 -> 22 | U31: =($Q31/5)*1 -> 11 | V31: 20 | W31: Available | X31: Wheat | Y31: 3
A32: 36 | B32: GAZEBO | C32: GFF172R | D32: Coconut & Coriander Bhaji | E32: Snacks | F32: Onion Bhaji's | G32: Produced | H32: Regular | I32: 1035 | J32: CCB20G | K32: Coconut & Coriander Bhaji 20G | L32: 20 | M32: Y | N32: Discontinued | O32: 900 | P32: =K32&" - "& C32 -> Coconut & Coriander Bhaji 20G - GFF172R | Q32: 55 | R32: 44 | S32: 33 | T32: 22 | U32: 11 | V32: 0 | W32: Available | X32: - | Y32: -
A33: 37 | B33: GAZEBO | C33: GFF014R | D33: Chicken Pakora | E33: Snacks | F33: Pakora's | G33: Produced | H33: Regular | I33: 1036 | J33: CPCOCG | K33: Chicken Pakora Cocktail | L33: Var | M33: N | N33: Discontinued | O33: 30 | P33: =K33&" - "& C33 -> Chicken Pakora Cocktail - GFF014R | Q33: 0 | R33: =($Q33/5)*4 -> 0 | S33: =($Q33/5)*3 -> 0 | T33: =($Q33/5)*2 -> 0 | U33: =($Q33/5)*1 -> 0 | V33: 0 | W33: Available | X33: Barley | Y33: 3
A34: 38 | B34: GAZEBO | C34: GFF013-3R | D34: Vegetable Pakora | E34: Snacks | F34: Pakora's | G34: Produced | H34: Regular | I34: 1037 | J34: VP12G | K34: Vegetable Pakora Bite 12G | L34: 12 | M34: Y | N34: Discontinued | O34: 1600 | P34: =K34&" - "& C34 -> Vegetable Pakora Bite 12G - GFF013-3R | Q34: 100 | R34: 80 | S34: 60 | T34: 40 | U34: 20 | V34: 0 | W34: Available | X34: Wheat | Y34: 3 | Z34: D-26/09/2022
A35: 39 | B35: GAZEBO | C35: GFF013-2R | D35: Vegetable Pakora | E35: Snacks | F35: Pakora's | G35: Produced | H35: Regular | I35: 1038 | J35: VP30G | K35: Vegetable Pakora Cocktail 30G | L35: 30 | M35: Y | N35: Discontinued | O35: 1412 | P35: =K35&" - "& C35 -> Vegetable Pakora Cocktail 30G - GFF013-2R | Q35: 60 | R35: =($Q35/5)*4 -> 48 | S35: =($Q35/5)*3 -> 36 | T35: =($Q35/5)*2 -> 24 | U35: =($Q35/5)*1 -> 12 | V35: 0 | W35: Available | X35: Wheat | Y35: 3 | Z35: D-05/10/2022
A36: 40 | B36: GAZEBO | C36: GFF013-1R | D36: Vegetable Pakora | E36: Snacks | F36: Pakora's | G36: Produced | H36: Regular | I36: 1039 | J36: VP100G | K36: Vegetable Pakora Large 100G | L36: 100 | M36: Y | N36: Discontinued | O36: 200 | P36: =K36&" - "& C36 -> Vegetable Pakora Large 100G - GFF013-1R | Q36: 45 | R36: =($Q36/5)*4 -> 36 | S36: =($Q36/5)*3 -> 27 | T36: =($Q36/5)*2 -> 18 | U36: =($Q36/5)*1 -> 9 | V36: 0 | W36: Available | X36: Wheat | Y36: 3 | Z36: D-05/10/2022
A37: 42 | B37: GAZEBO | C37: GFF045R | D37: Lamb Mediterranean Rolls | E37: Snacks | F37: Wraps | G37: Produced | H37: Regular | I37: 1041 | J37: LMR120G | K37: Lamb Medditerranean Rolls 120G | L37: 120 | M37: N | N37: Discontinued | O37: 225 | P37: =K37&" - "& C37 -> Lamb Medditerranean Rolls 120G - GFF045R | Q37: 4 | R37: 3.2 | S37: 2.4 | T37: 1.6 | U37: 0.8 | V37: 0 | W37: Available | X37: - | Y37: -
A38: 43 | B38: GAZEBO | C38: GFF044R | D38: Chicken Mediterranean Rolls | E38: Snacks | F38: Wraps | G38: Produced | H38: Regular | I38: 1042 | J38: CMR120G | K38: Chicken Medditerranean Rolls 120G | L38: 120 | M38: N | N38: Discontinued | O38: 225 | P38: =K38&" - "& C38 -> Chicken Medditerranean Rolls 120G - GFF044R | Q38: 4 | R38: 3.2 | S38: 2.4 | T38: 1.6 | U38: 0.8 | V38: 20 | W38: Available | X38: - | Y38: -
A39: 135 | B39: GAZEBO | C39: GFF113R | D39: Chicken Spring roll | E39: Snacks | F39: Chicken Spring roll's | G39: Produced | H39: Regular | I39: 1134 | J39: CSR50G1 | K39: Chicken Spring Roll Medium 50G- R1 | L39: 50 | M39: N | N39: Discontinued | O39: 675 | P39: =K39&" - "& C39 -> Chicken Spring Roll Medium 50G- R1 - GFF113R | Q39: 35 | R39: 28 | S39: 21 | T39: 14 | U39: 7 | V39: 20 | W39: Available | X39: Wheat, Soya | Y39: 3 | Z39: D-14/10/2022
A40: 136 | B40: GAZEBO | C40: GFF114R | D40: Vegetable Spring roll | E40: Snacks | F40: Vegetable Spring roll's | G40: Produced | H40: Regular | I40: 1135 | J40: VSR50G1 | K40: Vegetable Spring Roll Medium 50G- R1 | L40: 50 | M40: Y | N40: Live | O40: 3700 | P40: =K40&" - "& C40 -> Vegetable Spring Roll Medium 50G- R1 - GFF114R | Q40: 30 | R40: =($Q40/5)*4 -> 24 | S40: =($Q40/5)*3 -> 18 | T40: =($Q40/5)*2 -> 12 | U40: =($Q40/5)*1 -> 6 | V40: 20 | W40: Available | X40: Wheat, Soya | Y40: 3
...

Sheet Changes
A1: Date | B1: Description
A2: 42830 | B2: Mexican Burger Qty Per Batch Changed
A3: 42849 | B3: Added New Products
A4: 42858 | B4: Changed Qty Per Batch for Gff009-1r (30g & 100g) as per sanjays (gm) email
A5: 42867 | B5: Changed Qty Per Batch for Gff009-1r (30g as per sanjays (gm) Call
A6: 42874 | B6: Changed Qty Per Batch For GFF166-R ( 50G as per Sanjay (gm) verbal request
A7: 42894 | B7: Added Chapatiman New Products
A8: 42899 | B8: Changed Chapatiman Recipe Description
A9: 42942 | B9: Changed ob hf gff code to gff009-1r as per sanjays email
A10: 42951 | B10: Added New Contents Freshfayre Pot Meals
A11: 42972 | B11: GFF036R - FALAFAL RECIPE CHANGE OVER AS PER EMAILS FROM QA CHANGED AMOUNT PER BATCH FROM 450 - 390
A12: 42996 | B12: added new contents for whole foods items and ameded 1 item (money bag)
A13: 43024 | B13: Added new content for freshfayre sweet potatos
... A203: 46232 | B203: Added Danora musgrave chicen samosa

Sheet Mater Recipe Sheet
A1: No. | B1: Origin | C1: Recipe Reference | D1: Recipe Name | E1: Category | F1: Sub Category | G1: Out Sourced / Produced ? | H1: Regular /Occasional | I1: Alternative Code | J1: Code | K1: Description | L1: Unit Weight | M1: Vegetarian (Y,N) | N1: Status | O1: One Mix Qty/ Qty Per Batch | P1: PURCHASE CODE | Q1: PURCHASE INGREDIENT NAME | R1: SUPPLIER | S1: INGREDIENTS | T1: DEPARTMENT | U1: AMOUNT PER BATCH | V1: REMARK
A2: 4 | B2: GAZEBO | C2: GFF106R | D2: Chicken Tikka Samosa | E2: Snacks | F2: Chicken Samosa's | G2: Produced | H2: Regular | I2: 1003 | J2: CTS120G | K2: Chicken Tikka Samosa XL (Jumbo) 120G | L2: 120 | M2: N | N2: Live | O2: 320 | P2: - | Q2: - | R2: - | S2: Chicken | T2: PREPARATION | U2: 2640 | V2: -
A3: 4 | B3: GAZEBO | C3: GFF106R | D3: Chicken Tikka Samosa | E3: Snacks | F3: Chicken Samosa's | G3: Produced | H3: Regular | I3: 1003 | J3: CTS120G | K3: Chicken Tikka Samosa XL (Jumbo) 120G | L3: 120 | M3: N | N3: Live | O3: 320 | P3: - | Q3: - | R3: - | S3: Onions | T3: PREPARATION | U3: 2640 | V3: -
A4: 4 | B4: GAZEBO | C4: GFF106R | D4: Chicken Tikka Samosa | E4: Snacks | F4: Chicken Samosa's | G4: Produced | H4: Regular | I4: 1003 | J4: CTS120G | K4: Chicken Tikka Samosa XL (Jumbo) 120G | L4: 120 | M4: N | N4: Live | O4: 320 | P4: - | Q4: - | R4: - | S4: Peas | T4: PREPARATION | U4: 2400 | V4: -
A5: 4 | B5: GAZEBO | C5: GFF106R | D5: Chicken Tikka Samosa | E5: Snacks | F5: Chicken Samosa's | G5: Produced | H5: Regular | I5: 1003 | J5: CTS120G | K5: Chicken Tikka Samosa XL (Jumbo) 120G | L5: 120 | M5: N | N5: Live | O5: 320 | P5: - | Q5: - | R5: - | S5: Soya Mince | T5: PREPARATION | U5: 1600 | V5: -
A6: 4 | B6: GAZEBO | C6: GFF106R | D6: Chicken Tikka Samosa | E6: Snacks | F6: Chicken Samosa's | G6: Produced | H6: Regular | I6: 1003 | J6: CTS120G | K6: Chicken Tikka Samosa XL (Jumbo) 120G | L6: 120 | M6: N | N6: Live | O6: 320 | P6: - | Q6: - | R6: - | S6: Water | T6: PREPARATION | U6: 1330 | V6: -
A7: 4 | B7: GAZEBO | C7: GFF106R | D7: Chicken Tikka Samosa | E7: Snacks | F7: Chicken Samosa's | G7: Produced | H7: Regular | I7: 1003 | J7: CTS120G | K7: Chicken Tikka Samosa XL (Jumbo) 120G | L7: 120 | M7: N | N7: Live | O7: 320 | P7: - | Q7: - | R7: - | S7: Potato | T7: PREPARATION | U7: 1070 | V7: -
A8: 4 | B8: GAZEBO | C8: GFF106R | D8: Chicken Tikka Samosa | E8: Snacks | F8: Chicken Samosa's | G8: Produced | H8: Regular | I8: 1003 | J8: CTS120G | K8: Chicken Tikka Samosa XL (Jumbo) 120G | L8: 120 | M8: N | N8: Live | O8: 320 | P8: - | Q8: - | R8: - | S8: Lemon Juice | T8: PREPARATION | U8: 460 | V8: -
A9: 4 | B9: GAZEBO | C9: GFF106R | D9: Chicken Tikka Samosa | E9: Snacks | F9: Chicken Samosa's | G9: Produced | H9: Regular | I9: 1003 | J9: CTS120G | K9: Chicken Tikka Samosa XL (Jumbo) 120G | L9: 120 | M9: N | N9: Live | O9: 320 | P9: - | Q9: - | R9: - | S9: Tikka Seasoning | T9: SPICE | U9: 270 | V9: -
A10: 4 | B10: GAZEBO | C10: GFF106R | D10: Chicken Tikka Samosa | E10: Snacks | F10: Chicken Samosa's | G10: Produced | H10: Regular | I10: 1003 | J10: CTS120G | K10: Chicken Tikka Samosa XL (Jumbo) 120G | L10: 120 | M10: N | N10: Live | O10: 320 | P10: - | Q10: - | R10: - | S10: Sugar | T10: SPICE | U10: 70 | V10: -
A11: 4 | B11: GAZEBO | C11: GFF106R | D11: Chicken Tikka Samosa | E11: Snacks | F11: Chicken Samosa's | G11: Produced | H11: Regular | I11: 1003 | J11: CTS120G | K11: Chicken Tikka Samosa XL (Jumbo) 120G | L11: 120 | M11: N | N11: Live | O11: 320 | P11: - | Q11: - | R11: - | S11: Whole Cumin | T11: SPICE | U11: 40 | V11: -
A12: 4 | B12: GAZEBO | C12: GFF106R | D12: Chicken Tikka Samosa | E12: Snacks | F12: Chicken Samosa's | G12: Produced | H12: Regular | I12: 1003 | J12: CTS120G | K12: Chicken Tikka Samosa XL (Jumbo) 120G | L12: 120 | M12: N | N12: Live | O12: 320 | P12: - | Q12: - | R12: - | S12: Chilli Powder | T12: SPICE | U12: 40 | V12: -
A13: 4 | B13: GAZEBO | C13: GFF106R | D13: Chicken Tikka Samosa | E13: Snacks | F13: Chicken Samosa's | G13: Produced | H13: Regular | I13: 1003 | J13: CTS120G | K13: Chicken Tikka Samosa XL (Jumbo) 120G | L13: 120 | M13: N | N13: Live | O13: 320 | P13: - | Q13: - | R13: - | S13: Garam Masala | T13: SPICE | U13: 40 | V13: -
A14: 4 | B14: GAZEBO | C14: GFF106R | D14: Chicken Tikka Samosa | E14: Snacks | F14: Chicken Samosa's | G14: Produced | H14: Regular | I14: 1003 | J14: CTS120G | K14: Chicken Tikka Samosa XL (Jumbo) 120G | L14: 120 | M14: N | N14: Live | O14: 320 | P14: - | Q14: - | R14: - | S14: - | T14: - | U14: - | V14: -
A15: 4 | B15: GAZEBO | C15: GFF106R | D15: Chicken Tikka Samosa | E15: Snacks | F15: Chicken Samosa's | G15: Produced | H15: Regular | I15: 1003 | J15: CTS120G | K15: Chicken Tikka Samosa XL (Jumbo) 120G | L15: 120 | M15: N | N15: Live | O15: 320 | P15: - | Q15: - | R15: - | S15: - | T15: - | U15: - | V15: -
A16: 4 | B16: GAZEBO | C16: GFF106R | D16: Chicken Tikka Samosa | E16: Snacks | F16: Chicken Samosa's | G16: Produced | H16: Regular | I16: 1003 | J16: CTS120G | K16: Chicken Tikka Samosa XL (Jumbo) 120G | L16: 120 | M16: N | N16: Live | O16: 320 | P16: - | Q16: - | R16: - | S16: - | T16: - | U16: - | V16: -
A17: 4 | B17: GAZEBO | C17: GFF106R | D17: Chicken Tikka Samosa | E17: Snacks | F17: Chicken Samosa's | G17: Produced | H17: Regular | I17: 1003 | J17: CTS120G | K17: Chicken Tikka Samosa XL (Jumbo) 120G | L17: 120 | M17: N | N17: Live | O17: 320 | P17: - | Q17: - | R17: - | S17: - | T17: - | U17: - | V17: -
A18: 4 | B18: GAZEBO | C18: GFF106R | D18: Chicken Tikka Samosa | E18: Snacks | F18: Chicken Samosa's | G18: Produced | H18: Regular | I18: 1003 | J18: CTS120G | K18: Chicken Tikka Samosa XL (Jumbo) 120G | L18: 120 | M18: N | N18: Live | O18: 320 | P18: - | Q18: - | R18: - | S18: - | T18: - | U18: - | V18: -
A19: 4 | B19: GAZEBO | C19: GFF106R | D19: Chicken Tikka Samosa | E19: Snacks | F19: Chicken Samosa's | G19: Produced | H19: Regular | I19: 1003 | J19: CTS120G | K19: Chicken Tikka Samosa XL (Jumbo) 120G | L19: 120 | M19: N | N19: Live | O19: 320 | P19: - | Q19: - | R19: - | S19: - | T19: - | U19: - | V19: -
A20: 4 | B20: GAZEBO | C20: GFF106R | D20: Chicken Tikka Samosa | E20: Snacks | F20: Chicken Samosa's | G20: Produced | H20: Regular | I20: 1003 | J20: CTS120G | K20: Chicken Tikka Samosa XL (Jumbo) 120G | L20: 120 | M20: N | N20: Live | O20: 320 | P20: - | Q20: - | R20: - | S20: - | T20: - | U20: - | V20: -
A21: 4 | B21: GAZEBO | C21: GFF106R | D21: Chicken Tikka Samosa | E21: Snacks | F21: Chicken Samosa's | G21: Produced | H21: Regular | I21: 1003 | J21: CTS120G | K21: Chicken Tikka Samosa XL (Jumbo) 120G | L21: 120 | M21: N | N21: Live | O21: 320 | P21: - | Q21: - | R21: - | S21: - | T21: - | U21: - | V21: -
A22: 4 | B22: GAZEBO | C22: GFF106R | D22: Chicken Tikka Samosa | E22: Snacks | F22: Chicken Samosa's | G22: Produced | H22: Regular | I22: 1003 | J22: CTS120G | K22: Chicken Tikka Samosa XL (Jumbo) 120G | L22: 120 | M22: N | N22: Live | O22: 320 | P22: - | Q22: - | R22: - | S22: - | T22: - | U22: - | V22: -
A23: - | B23: - | C23: - | D23: - | E23: - | F23: - | G23: - | H23: - | I23: - | J23: - | K23: - | L23: - | M23: - | N23: - | O23: - | P23: - | Q23: - | R23: - | S23: - | T23: - | U23: - | V23: -
A24: 5 | B24: GAZEBO | C24: GFF004R | D24: Chicken Tikka Samosa | E24: Snacks | F24: Chicken Samosa's | G24: Produced | H24: Regular | I24: 1004 | J24: CTS100G | K24: Chicken Tikka Samosa Large 100G | L24: 100 | M24: N | N24: Live | O24: 600 | P24: - | Q24: - | R24: - | S24: Diced Chicken | T24: PREPARATION | U24: 9900 | V24: -
A25: 5 | B25: GAZEBO | C25: GFF004R | D25: Chicken Tikka Samosa | E25: Snacks | F25: Chicken Samosa's | G25: Produced | H25: Regular | I25: 1004 | J25: CTS100G | K25: Chicken Tikka Samosa Large 100G | L25: 100 | M25: N | N25: Live | O25: 600 | P25: - | Q25: - | R25: - | S25: Diced Onions | T25: PREPARATION | U25: 9900 | V25: -
A26: 5 | B26: GAZEBO | C26: GFF004R | D26: Chicken Tikka Samosa | E26: Snacks | F26: Chicken Samosa's | G26: Produced | H26: Regular | I26: 1004 | J26: CTS100G | K26: Chicken Tikka Samosa Large 100G | L26: 100 | M26: N | N26: Live | O26: 600 | P26: - | Q26: - | R26: - | S26: Peas | T26: PREPARATION | U26: 9900 | V26: -
A27: 5 | B27: GAZEBO | C27: GFF004R | D27: Chicken Tikka Samosa | E27: Snacks | F27: Chicken Samosa's | G27: Produced | H27: Regular | I27: 1004 | J27: CTS100G | K27: Chicken Tikka Samosa Large 100G | L27: 100 | M27: N | N27: Live | O27: 600 | P27: - | Q27: - | R27: - | S27: Soya Mince | T27: PREPARATION | U27: 4950 | V27: -
A28: 5 | B28: GAZEBO | C28: GFF004R | D28: Chicken Tikka Samosa | E28: Snacks | F28: Chicken Samosa's | G28: Produced | H28: Regular | I28: 1004 | J28: CTS100G | K28: Chicken Tikka Samosa Large 100G | L28: 100 | M28: N | N28: Live | O28: 600 | P28: - | Q28: - | R28: - | S28: Water | T28: PREPARATION | U28: 3960 | V28: -
A29: 5 | B29: GAZEBO | C29: GFF004R | D29: Chicken Tikka Samosa | E29: Snacks | F29: Chicken Samosa's | G29: Produced | H29: Regular | I29: 1004 | J29: CTS100G | K29: Chicken Tikka Samosa Large 100G | L29: 100 | M29: N | N29: Live | O29: 600 | P29: - | Q29: - | R29: - | S29: Lemon Juice | T29: PREPARATION | U29: 1485 | V29: -
A30: 5 | B30: GAZEBO | C30: GFF004R | D30: Chicken Tikka Samosa | E30: Snacks | F30: Chicken Samosa's | G30: Produced | H30: Regular | I30: 1004 | J30: CTS100G | K30: Chicken Tikka Samosa Large 100G | L30: 100 | M30: N | N30: Live | O30: 600 | P30: - | Q30: - | R30: - | S30: Sugar | T30: SPICE | U30: 240 | V30: -
A31: 5 | B31: GAZEBO | C31: GFF004R | D31: Chicken Tikka Samosa | E31: Snacks | F31: Chicken Samosa's | G31: Produced | H31: Regular | I31: 1004 | J31: CTS100G | K31: Chicken Tikka Samosa Large 100G | L31: 100 | M31: N | N31: Live | O31: 600 | P31: - | Q31: - | R31: - | S31: Whole Cumin | T31: SPICE | U31: 100 | V31: -
A32: 5 | B32: GAZEBO | C32: GFF004R | D32: Chicken Tikka Samosa | E32: Snacks | F32: Chicken Samosa's | G32: Produced | H32: Regular | I32: 1004 | J32: CTS100G | K32: Chicken Tikka Samosa Large 100G | L32: 100 | M32: N | N32: Live | O32: 600 | P32: - | Q32: - | R32: - | S32: Chilli Powder | T32: SPICE | U32: 75 | V32: -
A33: 5 | B33: GAZEBO | C33: GFF004R | D33: Chicken Tikka Samosa | E33: Snacks | F33: Chicken Samosa's | G33: Produced | H33: Regular | I33: 1004 | J33: CTS100G | K33: Chicken Tikka Samosa Large 100G | L33: 100 | M33: N | N33: Live | O33: 600 | P33: - | Q33: - | R33: - | S33: Tikka Seasoning | T33: SPICE | U33: 2180 | V33: -
A34: 5 | B34: GAZEBO | C34: GFF004R | D34: Chicken Tikka Samosa | E34: Snacks | F34: Chicken Samosa's | G34: Produced | H34: Regular | I34: 1004 | J34: CTS100G | K34: Chicken Tikka Samosa Large 100G | L34: 100 | M34: N | N34: Live | O34: 600 | P34: - | Q34: - | R34: - | S34: - | T34: - | U34: - | V34: -
A35: 5 | B35: GAZEBO | C35: GFF004R | D35: Chicken Tikka Samosa | E35: Snacks | F35: Chicken Samosa's | G35: Produced | H35: Regular | I35: 1004 | J35: CTS100G | K35: Chicken Tikka Samosa Large 100G | L35: 100 | M35: N | N35: Live | O35: 600 | P35: - | Q35: - | R35: - | S35: - | T35: - | U35: - | V35: -
A36: 5 | B36: GAZEBO | C36: GFF004R | D36: Chicken Tikka Samosa | E36: Snacks | F36: Chicken Samosa's | G36: Produced | H36: Regular | I36: 1004 | J36: CTS100G | K36: Chicken Tikka Samosa Large 100G | L36: 100 | M36: N | N36: Live | O36: 600 | P36: - | Q36: - | R36: - | S36: - | T36: - | U36: - | V36: -
A37: 5 | B37: GAZEBO | C37: GFF004R | D37: Chicken Tikka Samosa | E37: Snacks | F37: Chicken Samosa's | G37: Produced | H37: Regular | I37: 1004 | J37: CTS100G | K37: Chicken Tikka Samosa Large 100G | L37: 100 | M37: N | N37: Live | O37: 600 | P37: - | Q37: - | R37: - | S37: - | T37: - | U37: - | V37: -
A38: 5 | B38: GAZEBO | C38: GFF004R | D38: Chicken Tikka Samosa | E38: Snacks | F38: Chicken Samosa's | G38: Produced | H38: Regular | I38: 1004 | J38: CTS100G | K38: Chicken Tikka Samosa Large 100G | L38: 100 | M38: N | N38: Live | O38: 600 | P38: - | Q38: - | R38: - | S38: - | T38: - | U38: - | V38: -
A39: 5 | B39: GAZEBO | C39: GFF004R | D39: Chicken Tikka Samosa | E39: Snacks | F39: Chicken Samosa's | G39: Produced | H39: Regular | I39: 1004 | J39: CTS100G | K39: Chicken Tikka Samosa Large 100G | L39: 100 | M39: N | N39: Live | O39: 600 | P39: - | Q39: - | R39: - | S39: - | T39: - | U39: - | V39: -
A40: 5 | B40: GAZEBO | C40: GFF004R | D40: Chicken Tikka Samosa | E40: Snacks | F40: Chicken Samosa's | G40: Produced | H40: Regular | I40: 1004 | J40: CTS100G | K40: Chicken Tikka Samosa Large 100G | L40: 100 | M40: N | N40: Live | O40: 600 | P40: - | Q40: - | R40: - | S40: - | T40: - | U40: - | V40: -
...
