Workbook

Sheet Sheet1
A1: Supplier | B1: Purchase Code | C1: Purchase Ingredient Name | D1: Pack Size (Kg) | E1: Ingredients (G) | F1: Ingredients (KG) | G1: Bags/Qty Required | H1: our stock | I1: pack size | J1: simmers 27/07 | K1: cooks 28/07 | L1: Oakhhouse 29/07 | M1: Mindfull 30/07 | N1: Total 03-Aug Simmers+J+K+L+M | O1: status
A2: DAREGAL GOURMET UK LTD | B2: RMDAR001-01 | C2: Coriander | D2: 1 | E2: 59265.13 | F2: 59.26513 | G2: 59.26513 | H2: =IFERROR(VLOOKUP(B2,Sheet2!$A$2:$J$314,10,FALSE),0) -> 28 | I2: =IFERROR(VLOOKUP(B2,Sheet2!$A$2:$J$314,4,FALSE),0) -> 1 x 15kg | J2: =IFERROR(VLOOKUP(B2,[1]Sheet1!$B$5:$G$30,6,FALSE),0) -> 56.739304 | K2: =IFERROR(VLOOKUP(B2,[2]Sheet1!$B$5:$G$27,6,FALSE),0) -> 0 | L2: =IFERROR(VLOOKUP(B2,[3]Sheet1!$B$5:$G$27,6,FALSE),0) -> 2.3336727 | M2: =IFERROR(VLOOKUP(B2,[4]Sheet1!$B$5:$G$34,6,FALSE),0) -> 92.076857 | N2: =G2+J2+K2+L2+M2 -> 210.41496 | O2: okay
A3: DAREGAL GOURMET UK LTD | B3: RMDAR001-20 | C3: Garlic Diced 4mm China (1x10kg) | D3: 1 | E3: 26987.061 | F3: 26.987061 | G3: 26.987061 | H3: =IFERROR(VLOOKUP(B3,Sheet2!$A$2:$J$314,10,FALSE),0) -> 29.619 | I3: =IFERROR(VLOOKUP(B3,Sheet2!$A$2:$J$314,4,FALSE),0) -> 1 X 10KG | J3: =IFERROR(VLOOKUP(B3,[1]Sheet1!$B$5:$G$30,6,FALSE),0) -> 0 | K3: =IFERROR(VLOOKUP(B3,[2]Sheet1!$B$5:$G$27,6,FALSE),0) -> 0 | L3: =IFERROR(VLOOKUP(B3,[3]Sheet1!$B$5:$G$27,6,FALSE),0) -> 0 | M3: =IFERROR(VLOOKUP(B3,[4]Sheet1!$B$5:$G$34,6,FALSE),0) -> 0 | N3: =G3+J3+K3+L3+M3 -> 26.987061 | O3: okay
A4: KTC (EDIBLES) LTD | B4: RMKTC001-13 | C4: Pomace Olive Oil | D4: 1 | E4: 194200.43 | F4: 194.20043 | G4: 194.20043 | H4: =IFERROR(VLOOKUP(B4,Sheet2!$A$2:$J$314,10,FALSE),0) -> 61 | I4: =IFERROR(VLOOKUP(B4,Sheet2!$A$2:$J$314,4,FALSE),0) -> 3 X 5L | J4: =IFERROR(VLOOKUP(B4,[1]Sheet1!$B$5:$G$30,6,FALSE),0) -> 76.751061 | K4: =IFERROR(VLOOKUP(B4,[2]Sheet1!$B$5:$G$27,6,FALSE),0) -> 0 | L4: =IFERROR(VLOOKUP(B4,[3]Sheet1!$B$5:$G$27,6,FALSE),0) -> 0 | M4: =IFERROR(VLOOKUP(B4,[4]Sheet1!$B$5:$G$34,6,FALSE),0) -> 0 | N4: =G4+J4+K4+L4+M4 -> 270.9515 | O4: okay
A5: Eurocebollas | B5: RMEUR002-01 | C5: ONION PUREE | D5: 20 | E5: 28447.2 | F5: 28.4472 | G5: 1.42236 | H5: =IFERROR(VLOOKUP(B5,Sheet2!$A$2:$J$314,10,FALSE),0) -> 116 | I5: =IFERROR(VLOOKUP(B5,Sheet2!$A$2:$J$314,4,FALSE),0) -> 1 X 20 kg | J5: =IFERROR(VLOOKUP(B5,[1]Sheet1!$B$5:$G$30,6,FALSE),0) -> 0 | K5: =IFERROR(VLOOKUP(B5,[2]Sheet1!$B$5:$G$27,6,FALSE),0) -> 0 | L5: =IFERROR(VLOOKUP(B5,[3]Sheet1!$B$5:$G$27,6,FALSE),0) -> 3.8894545 | M5: =IFERROR(VLOOKUP(B5,[4]Sheet1!$B$5:$G$34,6,FALSE),0) -> 3.9098182 | N5: =G5+J5+K5+L5+M5 -> 9.2216327 | O5: okay
A6: Ellsey & Co Lancs Ltd | B6: RMELL001-01 | C6: 5% Rice Vinegar 25 litres | D6: 1 | E6: 227577.6 | F6: 227.5776 | G6: 227.5776 | H6: =IFERROR(VLOOKUP(B6,Sheet2!$A$2:$J$314,10,FALSE),0) -> 49 | I6: =IFERROR(VLOOKUP(B6,Sheet2!$A$2:$J$314,4,FALSE),0) -> 1 X 25L | J6: =IFERROR(VLOOKUP(B6,[1]Sheet1!$B$5:$G$30,6,FALSE),0) -> 0 | K6: =IFERROR(VLOOKUP(B6,[2]Sheet1!$B$5:$G$27,6,FALSE),0) -> 0 | L6: =IFERROR(VLOOKUP(B6,[3]Sheet1!$B$5:$G$27,6,FALSE),0) -> 0 | M6: =IFERROR(VLOOKUP(B6,[4]Sheet1!$B$5:$G$34,6,FALSE),0) -> 4.4362791 | N6: =G6+J6+K6+L6+M6 -> 232.01388 | O6: okay
A7: P&B FOODS LIMITED | B7: RMP&B001-14 | C7: HEERA XXL 1121 SELLA RICE(1x10kg) (MOQ:121) | D7: 1 | E7: 674676.52 | F7: 674.67652 | G7: 674.67652 | H7: =IFERROR(VLOOKUP(B7,Sheet2!$A$2:$J$314,10,FALSE),0) -> 284 | I7: =IFERROR(VLOOKUP(B7,Sheet2!$A$2:$J$314,4,FALSE),0) -> 1x10kg | J7: =IFERROR(VLOOKUP(B7,[1]Sheet1!$B$5:$G$30,6,FALSE),0) -> 488.384 | K7: =IFERROR(VLOOKUP(B7,[2]Sheet1!$B$5:$G$27,6,FALSE),0) -> 0 | L7: =IFERROR(VLOOKUP(B7,[3]Sheet1!$B$5:$G$27,6,FALSE),0) -> 283.94366 | M7: =IFERROR(VLOOKUP(B7,[4]Sheet1!$B$5:$G$34,6,FALSE),0) -> 0 | N7: =G7+J7+K7+L7+M7 -> 1447.0042 | O7: okay
A8: KENT FOODS LIMITED | B8: RMKEN003-01 | C8: SUCRANNA GRANULATED SUGAR ( Order 40 Bags) | D8: 1 | E8: 256024.8 | F8: 256.0248 | G8: 256.0248 | H8: =IFERROR(VLOOKUP(B8,Sheet2!$A$2:$J$314,10,FALSE),0) -> 37 | I8: =IFERROR(VLOOKUP(B8,Sheet2!$A$2:$J$314,4,FALSE),0) -> 1x25kg | J8: =IFERROR(VLOOKUP(B8,[1]Sheet1!$B$5:$G$30,6,FALSE),0) -> 0 | K8: =IFERROR(VLOOKUP(B8,[2]Sheet1!$B$5:$G$27,6,FALSE),0) -> 0 | L8: =IFERROR(VLOOKUP(B8,[3]Sheet1!$B$5:$G$27,6,FALSE),0) -> 23.336727 | M8: =IFERROR(VLOOKUP(B8,[4]Sheet1!$B$5:$G$34,6,FALSE),0) -> 0 | N8: =G8+J8+K8+L8+M8 -> 279.36153 | O8: okay
A9: KENT FOODS LIMITED | B9: RMKEN003-02 | C9: PDV SALT ( Order 49 Bags) | D9: 1 | E9: 21256.402 | F9: 21.256402 | G9: 21.256402 | H9: =IFERROR(VLOOKUP(B9,Sheet2!$A$2:$J$314,10,FALSE),0) -> 78 | I9: =IFERROR(VLOOKUP(B9,Sheet2!$A$2:$J$314,4,FALSE),0) -> 1x25kg | J9: =IFERROR(VLOOKUP(B9,[1]Sheet1!$B$5:$G$30,6,FALSE),0) -> 12.181363 | K9: =IFERROR(VLOOKUP(B9,[2]Sheet1!$B$5:$G$27,6,FALSE),0) -> 1.875 | L9: =IFERROR(VLOOKUP(B9,[3]Sheet1!$B$5:$G$27,6,FALSE),0) -> 6.2231273 | M9: =IFERROR(VLOOKUP(B9,[4]Sheet1!$B$5:$G$34,6,FALSE),0) -> 18.636175 | N9: =G9+J9+K9+L9+M9 -> 60.172067 | O9: okay
A10: BELFIELD FARMS ( YEARSLEY FOOD LTD) | B10: RMHAR002-09 | C10: DICED RED PEPPER 20MM | D10: 1 | E10: 312919.2 | F10: 312.9192 | G10: 312.9192 | H10: =IFERROR(VLOOKUP(B10,Sheet2!$A$2:$J$314,10,FALSE),0) -> 109.603 | I10: =IFERROR(VLOOKUP(B10,Sheet2!$A$2:$J$314,4,FALSE),0) -> 1 X 10KG | J10: =IFERROR(VLOOKUP(B10,[1]Sheet1!$B$5:$G$30,6,FALSE),0) -> 0 | K10: =IFERROR(VLOOKUP(B10,[2]Sheet1!$B$5:$G$27,6,FALSE),0) -> 0 | L10: =IFERROR(VLOOKUP(B10,[3]Sheet1!$B$5:$G$27,6,FALSE),0) -> 0 | M10: =IFERROR(VLOOKUP(B10,[4]Sheet1!$B$5:$G$34,6,FALSE),0) -> 286.34568 | N10: =G10+J10+K10+L10+M10 -> 599.26488 | O10: okay
A11: BELFIELD FARMS ( YEARSLEY FOOD LTD) | B11: RMFOO001-20 | C11: 30MM Cut Green Beans IQF (1x15kg) | D11: 1 | E11: 1560119.2 | F11: 1560.1192 | G11: 1560.1192 | H11: =IFERROR(VLOOKUP(B11,Sheet2!$A$2:$J$314,10,FALSE),0) -> 269.73333 | I11: =IFERROR(VLOOKUP(B11,Sheet2!$A$2:$J$314,4,FALSE),0) -> 1x15Kg | J11: =IFERROR(VLOOKUP(B11,[1]Sheet1!$B$5:$G$30,6,FALSE),0) -> 453.392 | K11: =IFERROR(VLOOKUP(B11,[2]Sheet1!$B$5:$G$27,6,FALSE),0) -> 0 | L11: =IFERROR(VLOOKUP(B11,[3]Sheet1!$B$5:$G$27,6,FALSE),0) -> 0 | M11: =IFERROR(VLOOKUP(B11,[4]Sheet1!$B$5:$G$34,6,FALSE),0) -> 0 | N11: =G11+J11+K11+L11+M11 -> 2013.5112 | O11: okay
A12: FOODNET LIMITED | B12: RMFOO001-15 | C12: Garlic Puree Tablet IQF (1x10kg) | D12: 1 | E12: 14223.6 | F12: 14.2236 | G12: 14.2236 | H12: =IFERROR(VLOOKUP(B12,Sheet2!$A$2:$J$314,10,FALSE),0) -> 51 | I12: =IFERROR(VLOOKUP(B12,Sheet2!$A$2:$J$314,4,FALSE),0) -> 1x10Kg | J12: =IFERROR(VLOOKUP(B12,[1]Sheet1!$B$5:$G$30,6,FALSE),0) -> 40.122261 | K12: =IFERROR(VLOOKUP(B12,[2]Sheet1!$B$5:$G$27,6,FALSE),0) -> 0 | L12: =IFERROR(VLOOKUP(B12,[3]Sheet1!$B$5:$G$27,6,FALSE),0) -> 3.8894545 | M12: =IFERROR(VLOOKUP(B12,[4]Sheet1!$B$5:$G$34,6,FALSE),0) -> 11.090698 | N12: =G12+J12+K12+L12+M12 -> 69.326013 | O12: okay
A13: BELFIELD FARMS ( YEARSLEY FOOD LTD) | B13: RMHAR002-34 | C13: IQF Red Chilli Puree | D13: 1 | E13: 29632.565 | F13: 29.632565 | G13: 29.632565 | H13: =IFERROR(VLOOKUP(B13,Sheet2!$A$2:$J$314,10,FALSE),0) -> 78.9 | I13: =IFERROR(VLOOKUP(B13,Sheet2!$A$2:$J$314,4,FALSE),0) -> 1 X 10KG | J13: =IFERROR(VLOOKUP(B13,[1]Sheet1!$B$5:$G$30,6,FALSE),0) -> 20.06113 | K13: =IFERROR(VLOOKUP(B13,[2]Sheet1!$B$5:$G$27,6,FALSE),0) -> 0 | L13: =IFERROR(VLOOKUP(B13,[3]Sheet1!$B$5:$G$27,6,FALSE),0) -> 0 | M13: =IFERROR(VLOOKUP(B13,[4]Sheet1!$B$5:$G$34,6,FALSE),0) -> 0 | N13: =G13+J13+K13+L13+M13 -> 49.693696 | O13: okay
... A27: EASTLAND INGREDIENTS LTD | B27: RMVIR001-82 | C27: Paprika Ground Heat Treated (1X25kg) | D27: 1 | E27: 3555.9 | F27: 3.5559 | G27: 3.5559 | H27: =IFERROR(VLOOKUP(B27,Sheet2!$A$2:$J$314,10,FALSE),0) -> 4 | I27: =IFERROR(VLOOKUP(B27,Sheet2!$A$2:$J$314,4,FALSE),0) -> 1 X 25KG | J27: =IFERROR(VLOOKUP(B27,[1]Sheet1!$B$5:$G$30,6,FALSE),0) -> 0 | K27: =IFERROR(VLOOKUP(B27,[2]Sheet1!$B$5:$G$27,6,FALSE),0) -> 0 | L27: =IFERROR(VLOOKUP(B27,[3]Sheet1!$B$5:$G$27,6,FALSE),0) -> 0 | M27: =IFERROR(VLOOKUP(B27,[4]Sheet1!$B$5:$G$34,6,FALSE),0) -> 0 | N27: =G27+J27+K27+L27+M27 -> 3.5559 | O27: okay
F28: 15 | H28: 100 | J28: 20 | K28: 30 | L28: 50
A31: Boxes
A32: Case Order Code | B32: Case Name | C32: Cases Required | D32: Total Cases Issued | E32: Trace Number | F32: Signature (Despatch Supervisor) | G32: Signature (Packing Supervisor) | J32: out stock | K32: simmers 27/07 | L32: Total 03-Aug+27 Aug | M32: status
A33: PKCON001-53 | B33: B187 TRAY BOX | C33: 1029.4 | J33: 1280 | K33: 658 | L33: 1687.4 | M33: Not Okay
A38: Tray
A39: Tray Order Code | B39: Tray Supplier | C39: Tray Inventory Code | D39: Name Of Tray | E39: Tray Qty | F39: our stock | G39: simmers 27/07 | H39: Total 03-Aug+27 Aug | I39: status
A40: PKNOV001-02 | B40: Novato Packaging BV | C40: B187/45 Cuisine Kraft Tray | D40: B187/45 | E40: 15968 | F40: 25500 | G40: 10380 | H40: =E40+G40 -> 26348 | I40: Not okay
A41: PKNOV001-01 | B41: Novato Packaging BV | C41: B187/60 Cuisine Kraft Tray | D41: B187/60 | E41: 3696 | F41: 25830 | G41: 2224 | H41: =E41+G41 -> 5920 | I41: Okay
A48: Inner label
A49: Sleeves/Labels | B49: Product Category | C49: Brand | D49: Inner Label | E49: Sleeve Ref | F49: Customer | G49: Packing Name | H49: Total Inner Labels/Sleeves Required | I49: our stock | J49: simmers 27/07 | K49: Total 03-Aug+27 Aug | L49: status
A50: Sleeves | B50: RETAIL-MEALS-SE | C50: Simmer Eats | D50: Inner - 1030 | E50: S187-04 | F50: SIMMER | G50: SE Std Sweet & Sour Chicken W/Egg Fried Rice | H50: 11234 | I50: 31200 | J50: =IFERROR(VLOOKUP(E50,[1]Sheet1!$D$64:$G$66,4,FALSE),0) -> 0 | K50: =H50+J50 -> 11234 | L50: okay
A51: Sleeves | B51: RETAIL-MEALS-SE | C51: Simmer Eats | D51: Inner - 1031 | E51: S187-05 | F51: SIMMER | G51: SE Lean Sweet & Sour Chicken W/Egg Fried Rice | H51: 4734 | I51: 4800 | J51: =IFERROR(VLOOKUP(E51,[1]Sheet1!$D$64:$G$66,4,FALSE),0) -> 0 | K51: =H51+J51 -> 4734 | L51: okay
A52: Sleeves | B52: RETAIL-MEALS-SE | C52: Simmer Eats | D52: Inner - 1032 | E52: S187-06 | F52: SIMMER | G52: SE Lrg Sweet & Sour Chicken W/Egg Fried Rice | H52: 3696 | I52: 19500 | J52: =IFERROR(VLOOKUP(E52,[1]Sheet1!$D$64:$G$66,4,FALSE),0) -> 0 | K52: =H52+J52 -> 3696 | L52: okay

Sheet Sheet2
A1: Stock Code | B1: Products | C1: Suppliers | D1: CASE SIZE | E1: Fraction | F1: Opening Stock | G1: IN | H1: OUT | J1: Closing stock
A2: RMF00003-01 | B2: NATURAL SOYA MINCE | C2: AZELIS UK LIFE SCIENCE LTD | D2: 1 x 15kg | E2: 1 | F2: 63 | G2: 168 | H2: 127 | I2: 127 | J2: 104
A3: RMAZE001-01 | B3: CLARIA PLUS STARCH | C3: AZELIS UK LIFE SCIENCE LTD | D3: 1 X 25KG | E3: 25 | F3: 6 | G3: 8 | H3: 150 | I3: 6 | J3: 8
A4: RMBAC001-01 | B4: NATIVE POTATO STARCH 25KG | C4: BACAREL & CO LIMITED | D4: 1X 25KG | E4: 1 | F4: 17 | G4: 40 | H4: 8 | I4: 8 | J4: 49
A5: RMBAC001-04 | B5: Preservative Free Potato Flake (1 x 20KG) | C5: BACAREL & CO LIMITED | D5: 1 x 20kg | E5: 20 | F5: 3 | G5: 5 | H5: 40 | I5: 2 | J5: 6
A6: RMBAK001-02 | B6: Tate and Lyle soft light brown sugar 1 x 25kg | C6: Bako London & S E Ltd | D6: 1 X 25KG | E6: 25 | F6: 0 | G6: 0 | H6: 0 | I6: 0 | J6: 0
A7: RMBAK001-03 | B7: Heat Treated Pumpkin Seeds | C7: Bako London & S E Ltd | D7: 1 X 25KG | E7: 25 | F7: 0 | G7: 0 | H7: 0 | I7: 0 | J7: 0
A8: RMBAK001-07 | B8: Light Brown Soft Sugar 1 x 25kg (MOQ 40 bags) | C8: Bako London & S E Ltd | D8: 1x25kg | E8: 25 | F8: 5 | G8: 0 | H8: 0 | I8: 0 | J8: 5
A9: RMHAR002-01 | B9: FROZEN PEAS | C9: BELFIELD FARMS (HARRY YEARSLEY LTD) | D9: 1 X10KG | E9: 1 | F9: 510 | G9: 1170 | H9: 1140 | I9: 1140 | J9: 540
A10: RMHAR001-02 | B10: leaf spinach portions (4x2.5 KG) | C10: BELFIELD FARMS (HARRY YEARSLEY LTD) | D10: (4x2.5 KG) | E10: 1 | F10: 21.5 | G10: 40 | H10: 29.05 | I10: 29.05 | J10: 32.45
A11: RMHAR002-02 | B11: FROZEN CHOPPED SPINACH | C11: BELFIELD FARMS (HARRY YEARSLEY LTD) | D11: 4 x 2.5 | E11: 4 | F11: 15.45 | G11: 10 | H11: 16.25 | I11: 4.0625 | J11: 21.3875
A12: RMHAR002-03 | B12: FROZEN MIX VEGETABLES | C12: BELFIELD FARMS (HARRY YEARSLEY LTD) | D12: 1 X10KG | E12: 1 | F12: 28 | G12: 0 | H12: 0 | I12: 0 | J12: 28
A13: RMHAR002-04 | B13: Broad Bean | C13: BELFIELD FARMS (HARRY YEARSLEY LTD) | D13: 1 x 10kg | E13: 10 | F13: 10.8 | G13: 0 | H13: 0 | I13: 0 | J13: 10.8
... A305: RMWEI001-02 | B305: Chicken Spring Roll 35g - 60pcs*4bags-8.4kg | C305: WEIFANG BIONH FOOD TECH CO. LTD | D305: 60x4 | E305: 1 | F305: 78 | G305: 0 | H305: 10 | I305: 10 | J305: 68
A306: RMWEI002-01 | B306: Chicken Samosa 40g - 60pcs*4 bags- 9.6kg | C306: WEIFANG BIONH FOOD TECH CO. LTD | D306: 9.6 | E306: 1 | F306: 49 | G306: 108 | H306: 69 | I306: 69 | J306: 88
A307: RMWEI002-02 | B307: Chicken Springroll 30g - 70pcs*4 bags- 8.4kg | C307: WEIFANG BIONH FOOD TECH CO. LTD | D307: 8.4 | E307: 1 | F307: 54 | G307: 48 | H307: 39 | I307: 39 | J307: 63
A308: RMWEI002-03 | B308: Veg Springroll 30g - 70pcs*4 bags- 8.4kg | C308: WEIFANG BIONH FOOD TECH CO. LTD | D308: 8.4 | E308: 1 | F308: 61 | G308: 165 | H308: 85 | I308: 85 | J308: 141
A309: RMWEI002-04 | B309: Veg Springroll 20g - 100pcs*4 bags- 8kg> | C309: WEIFANG BIONH FOOD TECH CO. LTD | D309: 8 | E309: 1 | F309: 0 | G309: 0 | H309: 0 | I309: 0 | J309: 0
A310: RMWES001-01 | B310: NEW: BALTI PASTE | C310: WEST MILL | D310: 1 X 25KG | E310: 1 | F310: 51 | G310: 0 | H310: 14 | I310: 14 | J310: 37
A311: RMWES001-02 | B311: G/DRAGN THAI FRAG RCE 1 X 20KG | C311: WEST MILL | D311: 1 x 20kg | E311: 1 | F311: 50 | G311: 0 | H311: 14 | I311: 14 | J311: 36
A312: RMWES001-05 | B312: AMOY HOISIN BBQ SCE 6X2.3KG | C312: WEST MILL | D312: 6x2.3 kg | E312: 6 | F312: 25.666667 | G312: 0 | H312: 65 | I312: 10.833333 | J312: 14.833333
A313: RMWES001-06 | B313: Thick Free-Range Egg Noodles (1x9kg) | C313: WEST MILL | D313: 1x9kg | E313: 1 | F313: 0 | G313: 40 | H313: 10 | I313: 10 | J313: 30
A314: RMWHI001-03 | B314: Quality Plain Flour | C314: WHITWORTH BROS.LTD | D314: 1 x 16kg | E314: 1 | F314: 94 | G314: 195 | H314: 133 | I314: 133 | J314: 156

Sheet Sheet3
A1: Stock Code | B1: Products | C1: Suppliers | E1: CASE SIZE | F1: Fraction | G1: Opening Stock | H1: IN | I1: OUT | J1: Closing stock
A2: Boxes
A3: PKCON001-03 | B3: 596 X 2 - 320 X 254 X 124 | C3: CONNECT PACKAGING | D3: box | E3: 1 X 640 | F3: 1 | G3: 2220 | H3: 18025 | I3: 14925 | J3: 5320
A4: PKCON001-07 | B4: SK4- 288 X 195 X 132 | C4: CONNECT PACKAGING | D4: box | E4: 1 X 960 | F4: 1 | G4: 2880 | H4: 2110 | I4: 3070 | J4: 1920
A5: PKCON001-08 | B5: SK45 X 6 - 345 X 218 X 145 | C5: CONNECT PACKAGING | D5: box | E5: 1 X 640 | F5: 1 | G5: 1720 | H5: 1920 | I5: 2160 | J5: 1480
A6: PKCON001-16 | B6: NEW MULTIPACK - 150K/150T 'B' FLUTE (450 X 350 X 165) - freezer | C6: CONNECT PACKAGING | D6: box | E6: 1 x 600 | F6: 1 | G6: 1200 | H6: 2240 | I6: 620 | J6: 2820
A7: PKCON001-19 | B7: GMB2 323 x 210 x 195mm | C7: CONNECT PACKAGING | D7: box | E7: 1 x 700 | F7: 1 | G7: 1025 | H7: 2100 | I7: 2500 | J7: 625
A8: PKCON001-20 | B8: NEW COSTCO 2 X 4 : 480 X 246 X 308(1 x 320) V1/12/24 | C8: CONNECT PACKAGING | D8: box | E8: 1 x 320 | F8: 1 | G8: 320 | H8: 1280 | I8: 960 | J8: 640
A9: PKCON001-23 | B9: NEW Duo Pot - ORANGE - 300 x 90 x 148 (1 x 2100) | C9: CONNECT PACKAGING | D9: box | E9: 1 x 2100 | F9: 1 | G9: 2075 | H9: 0 | I9: 375 | J9: 1700
A10: PKCON001-24 | B10: NEW Retail Pack - RED (300 x 148 x 189)(1X1200) | C10: CONNECT PACKAGING | D10: box | E10: 1 x 1200 | F10: 1 | G10: 0 | H10: 2400 | I10: 1200 | J10: 1200
A11: PKCON001-27 | B11: DUO POT - PLAIN 300 X 90 X 148 (1x2100) | C11: CONNECT PACKAGING | D11: box | E11: 1 x 2100 | F11: 1 | G11: 1925 | H11: 0 | I11: 125 | J11: 1800
A12: PKCON001-29 | B12: 2200- (310 x 210 x 95) (1 X 1050) | C12: CONNECT PACKAGING | D12: box | E12: 1 X 1050 | F12: 1 | G12: 1050 | H12: 8530 | I12: 7480 | J12: 2100
A13: PKCON001-30 | B13: 2200-2C (320 X 210 X 70) (1 x 525) | C13: CONNECT PACKAGING | D13: box | E13: 1 X 1050 | F13: 1 | G13: 1200 | H13: 0 | I13: -100 | J13: 1300
A14: PKCON001-31 | B14: 2171 - 1F ( 352 x 260 x 106) ( 1 x 640) | C14: CONNECT PACKAGING | D14: box | E14: 1 x 640 | F14: 1 | G14: 1200 | H14: 1515 | I14: 1400 | J14: 1315
... A23: PKCON001-53 | B23: B187 Tray box (382x283x248) (1x320) | C23: CONNECT PACKAGING | D23: box | E23: 1x320 | F23: 1 | G23: 0 | H23: 4480 | I23: 3200 | J23: 1280
A24: Trays | G24: 0 | H24: 0 | I24: 0 | J24: 0
A25: PKESS001-06 | B25: SK4 - SPLITCL1 | C25: ENVIROPAX LTD (ESSEX EXTRUSION) | D25: Tray | E25: 1 x 600 | F25: 1 | G25: 24600 | H25: 24000 | I25: 19800 | J25: 28800
A26: PKESS001-07 | B26: SK4-40CL1 | C26: ENVIROPAX LTD (ESSEX EXTRUSION) | D26: Tray | E26: 1 x 500 | F26: 1 | G26: 21500 | H26: 30000 | I26: 40500 | J26: 11000
A27: PKESS001-08 | B27: Wrap Tray - 180 x 100 x 47 - 1 X 1050 | C27: ENVIROPAX LTD (ESSEX EXTRUSION) | D27: Tray | E27: 1 X 1050 | F27: 1 | G27: 47250 | H27: 0 | I27: 5250 | J27: 42000
A28: PKESS001-09 | B28: Grab & Go SQ Tray (141 X 141X40)(1x900) | C28: ENVIROPAX LTD (ESSEX EXTRUSION) | D28: Tray | E28: 1 X 900 | F28: 1 | G28: 108000 | H28: 230400 | I28: 135000 | J28: 203400
A29: PKESS001-10 | B29: HW308/60 - 3 CAVITY TRANS - 352X246X60 | C29: ENVIROPAX LTD (ESSEX EXTRUSION) | D29: Tray | E29: 1 X 160 | F29: 1 | G29: 9920 | H29: 9600 | I29: 9600 | J29: 9920
A30: PKESS001-12 | B30: HW 308/60 TRANS OPEN ECO - 352X246X60 | C30: ENVIROPAX LTD (ESSEX EXTRUSION) | D30: Tray | E30: 1 X160 | F30: 1 | G30: 3840 | H30: 48000 | I30: 31520 | J30: 20320
A31: PKESS001-13 | B31: SK5-SPLITCL1 - 219x168x45(1x400) | C31: ENVIROPAX LTD (ESSEX EXTRUSION) | D31: Tray | E31: 1x400 | F31: 1 | G31: 12400 | H31: 24000 | I31: -12000 | J31: 48400
A32: PKPAC001-01 | B32: Flat Tray - 200x155x39 | C32: Pack Benefit | D32: Tray | E32: 1x5250 | F32: 1 | G32: 36755 | H32: 0 | I32: -745 | J32: 37500
A33: PKHUH001-02 | B33: Pie Tray - 170x120x49 | C33: Huhtamaki Lurgan Ltd | D33: Tray | E33: 1 X12960 | F33: 1 | G33: 7920 | H33: 0 | I33: 0 | J33: 7920
A34: PKLEE001-01 | B34: 2 X CAVITY DIP POT | C34: LEEWAYS PACKAGING SERVICES LTD | D34: Tray | E34: 1x 1050 | F34: 1 | G34: 19950 | H34: 0 | I34: 1050 | J34: 18900
A35: PKLEE001-05 | B35: Single Cavity Tray 149mm x 85mm x 43mm | C35: LEEWAYS PACKAGING SERVICES LTD | D35: Tray | E35: 1X1200 | F35: 1 | G35: 24000 | H35: 0 | I35: 1200 | J35: 22800
A36: PKLEE001-08 | B36: HW308/60 3 x cavity ECO Transparent | C36: LEEWAYS PACKAGING SERVICES LTD | D36: Tray | E36: 1 x 140 | F36: 1 | G36: 0 | H36: 0 | I36: 0 | J36: 0
... A51: PKNOV001-02 | B51: B187/45 Cuisine Kraft Tray | C51: Novato Packaging BV | D51: Tray | E51: 1 x 750 | F51: 1 | G51: 25500 | H51: 54000 | I51: 47250 | J51: 32250
A52: Film | G52: 0 | H52: 0 | I52: 0 | J52: 0
A53: PKCLI001-01 | B53: 25mu Weld Seal Mono PET Film (300mm x 1000lm) | C53: Clifton Packaging | D53: film | E53: 1x1000 | F53: 1 | G53: 66 | H53: 0 | I53: 2 | J53: 64
A54: PKCLI001-02 | B54: 25mu Weld Seal Mono PET Film (240mm x 1000lm) | C54: Cliffton Packaging | D54: film | E54: 1x1000 | F54: 1 | G54: 13 | H54: 0 | I54: 0 | J54: 13
A55: PKCLI001-04 | B55: 25mu Weld Seal Mono PET Film (340mm x 1000lm) | C55: Cliffton Packaging | D55: film | E55: 1x1000 | F55: 1 | G55: 0 | H55: 42 | I55: 14 | J55: 28
A56: PKKMP001-03 | B56: K peel 7G+25A/f-275mm (275mmX1000) (MOQ:60) | C56: KM PACKAGING SERVICES LTD | D56: film | E56: 1x1000 | F56: 1 | G56: 129 | H56: 0 | I56: 18 | J56: 111
A57: PKKMP001-04 | B57: K Peel 3G 25µm (275mmX1000lm)(MOQ:60) | C57: KM PACKAGING SERVICES LTD | D57: film | E57: 1 x 1000 | F57: 1 | G57: 25 | H57: 0 | I57: 4 | J57: 21
A58: PKKMP001-05 | B58: K Peel RPSM 25µm (340mmX1000lm)(MOQ:60) | C58: KM PACKAGING SERVICES LTD | D58: film | E58: 1X1000 | F58: 1 | G58: 90 | H58: 0 | I58: 3 | J58: 87
A59: PKKMP001-06 | B59: AF Weld Film (270mmX1000lm) | C59: KM PACKAGING SERVICES LTD | D59: film | E59: 1X1000 | F59: 1 | G59: 0 | H59: 0 | I59: 0 | J59: 0
A60: PKKMP001-07 | B60: AF Weld Film (300mmX1000lm) | C60: KM PACKAGING SERVICES LTD | D60: film | E60: 1X1000 | F60: 1 | G60: 0 | H60: 0 | I60: 0 | J60: 0
A61: PKKMP001-08 | B61: K peel 7G+25A/f-240mm (240mmX1000) | C61: KM PACKAGING SERVICES LTD | D61: film | E61: 1X1000 | F61: 1 | G61: 235 | H61: 0 | I61: 31 | J61: 204
A62: PKKMP001-09 | B62: K-Peel EIPS N 45 (250mmX850lm)(MOQ40) | C62: KM PACKAGING SERVICES LTD | D62: film | E62: 1X850 | F62: 1 | G62: 0 | H62: 40 | I62: 14 | J62: 26
...
